{
	"registryname":"starresearch_station",
	"localizedname":"mind.starresearch_station.name",
    "parts": [
        {
            "x": 0,
            "y": 0,
            "z": 0,
            "elements": [
                "modularmachinery:blockcontroller@2"
            ]
        },
        {
            "x": -1,
            "y": 0,
            "z": 0,
            "elements": [
                "minecraft:wool@4"
            ]
        },
        {
            "x": 1,
            "y": 0,
            "z": 0,
            "elements": [
                "minecraft:wool@1"
            ]
        },
        {
            "x": -1,
            "y": 6,
            "z": -1,
            "elements": [
                "minecraft:acacia_stairs@5"
            ]
        },
        {
            "x": 7,
            "y": 14,
            "z": -1,
            "elements": [
                "minecraft:wool@4"
            ]
        },
        {
            "x": 6,
            "y": 14,
            "z": -1,
            "elements": [
                "minecraft:wool@4"
            ]
        },
        {
            "x": -2,
            "y": 6,
            "z": -1,
            "elements": [
                "minecraft:wool@4"
            ]
        },
        {
            "x": 5,
            "y": 14,
            "z": -1,
            "elements": [
                "minecraft:acacia_stairs@0"
            ]
        },
        {
            "x": 7,
            "y": 17,
            "z": 0,
            "elements": [
                "astralsorcery:blockmachine@0"
            ]
        },
        {
            "x": 0,
            "y": 9,
            "z": 0,
            "elements": [
                "minecraft:acacia_stairs@0"
            ]
        },
        {
            "x": 1,
            "y": 9,
            "z": 0,
            "elements": [
                "minecraft:planks@4"
            ]
        },
        {
            "x": 3,
            "y": 11,
            "z": 1,
            "elements": [
                "minecraft:planks@4"
            ]
        },
        {
            "x": 2,
            "y": 9,
            "z": 0,
            "elements": [
                "minecraft:acacia_stairs@5"
            ]
        },
        {
            "x": 4,
            "y": 11,
            "z": 1,
            "elements": [
                "minecraft:wool@4"
            ]
        },
        {
            "x": 1,
            "y": -1,
            "z": 0,
            "elements": [
                "minecraft:stone_slab@9"
            ]
        },
        {
            "x": 0,
            "y": -1,
            "z": 0,
            "elements": [
                "minecraft:stone_slab@9"
            ]
        },
        {
            "x": 0,
            "y": 3,
            "z": 1,
            "elements": [
                "minecraft:planks@4"
            ]
        },
        {
            "x": 0,
            "y": 1,
            "z": 0,
            "elements": [
                "minecraft:oak_stairs@2"
            ]
        },
        {
            "x": -1,
            "y": -1,
            "z": 0,
            "elements": [
                "minecraft:stone_slab@9"
            ]
        },
        {
            "x": 6,
            "y": 13,
            "z": -1,
            "elements": [
                "minecraft:acacia_stairs@5"
            ]
        },
        {
            "x": 5,
            "y": 13,
            "z": -1,
            "elements": [
                "minecraft:planks@4"
            ]
        },
        {
            "x": 4,
            "y": 13,
            "z": -1,
            "elements": [
                "minecraft:acacia_stairs@0"
            ]
        },
        {
            "x": 7,
            "y": 18,
            "z": 0,
            "elements": [
                "astralsorcery:blockstructural@0"
            ]
        },
        {
            "x": 1,
            "y": 10,
            "z": 0,
            "elements": [
                "minecraft:acacia_stairs@0"
            ]
        },
        {
            "x": 3,
            "y": 12,
            "z": 1,
            "elements": [
                "minecraft:wool@4"
            ]
        },
        {
            "x": 2,
            "y": 10,
            "z": 0,
            "elements": [
                "minecraft:planks@4"
            ]
        },
        {
            "x": 4,
            "y": 12,
            "z": 1,
            "elements": [
                "minecraft:planks@4"
            ]
        },
        {
            "x": 3,
            "y": 10,
            "z": 0,
            "elements": [
                "minecraft:acacia_stairs@5"
            ]
        },
        {
            "x": 5,
            "y": 12,
            "z": 1,
            "elements": [
                "minecraft:acacia_stairs@5"
            ]
        },
        {
            "x": 0,
            "y": 6,
            "z": 2,
            "elements": [
                "minecraft:acacia_stairs@7"
            ]
        },
        {
            "x": 0,
            "y": 4,
            "z": 1,
            "elements": [
                "minecraft:planks@4"
            ]
        },
        {
            "x": 5,
            "y": 12,
            "z": -1,
            "elements": [
                "minecraft:acacia_stairs@5"
            ]
        },
        {
            "x": 4,
            "y": 12,
            "z": -1,
            "elements": [
                "minecraft:planks@4"
            ]
        },
        {
            "x": 3,
            "y": 12,
            "z": -1,
            "elements": [
                "minecraft:wool@4"
            ]
        },
        {
            "x": 2,
            "y": 11,
            "z": 0,
            "elements": [
                "minecraft:acacia_stairs@0"
            ]
        },
        {
            "x": 4,
            "y": 13,
            "z": 1,
            "elements": [
                "minecraft:acacia_stairs@0"
            ]
        },
        {
            "x": 3,
            "y": 11,
            "z": 0,
            "elements": [
                "minecraft:planks@4"
            ]
        },
        {
            "x": 5,
            "y": 13,
            "z": 1,
            "elements": [
                "minecraft:planks@4"
            ]
        },
        {
            "x": 4,
            "y": 11,
            "z": 0,
            "elements": [
                "minecraft:wool@4"
            ]
        },
        {
            "x": 6,
            "y": 13,
            "z": 1,
            "elements": [
                "minecraft:acacia_stairs@5"
            ]
        },
        {
            "x": -2,
            "y": 5,
            "z": 1,
            "elements": [
                "minecraft:acacia_stairs@4"
            ]
        },
        {
            "x": -1,
            "y": 7,
            "z": 2,
            "elements": [
                "minecraft:acacia_stairs@4"
            ]
        },
        {
            "x": 0,
            "y": 7,
            "z": 2,
            "elements": [
                "minecraft:planks@4"
            ]
        },
        {
            "x": 0,
            "y": 5,
            "z": 1,
            "elements": [
                "minecraft:planks@4"
            ]
        },
        {
            "x": 1,
            "y": 5,
            "z": 1,
            "elements": [
                "minecraft:acacia_stairs@5"
            ]
        },
        {
            "x": -1,
            "y": -1,
            "z": 2,
            "elements": [
                "minecraft:stone_slab@9"
            ]
        },
        {
            "x": 0,
            "y": -1,
            "z": 2,
            "elements": [
                "minecraft:stone_slab@9"
            ]
        },
        {
            "x": 1,
            "y": -1,
            "z": 2,
            "elements": [
                "minecraft:stone_slab@9"
            ]
        },
        {
            "x": 4,
            "y": 11,
            "z": -1,
            "elements": [
                "minecraft:wool@4"
            ]
        },
        {
            "x": 3,
            "y": 11,
            "z": -1,
            "elements": [
                "minecraft:acacia_stairs@4"
            ]
        },
        {
            "x": 3,
            "y": 12,
            "z": 0,
            "elements": [
                "minecraft:wool@4"
            ]
        },
        {
            "x": 5,
            "y": 14,
            "z": 1,
            "elements": [
                "minecraft:acacia_stairs@0"
            ]
        },
        {
            "x": 4,
            "y": 12,
            "z": 0,
            "elements": [
                "minecraft:planks@4"
            ]
        },
        {
            "x": -2,
            "y": 8,
            "z": 2,
            "elements": [
                "minecraft:acacia_stairs@4"
            ]
        },
        {
            "x": 6,
            "y": 14,
            "z": 1,
            "elements": [
                "minecraft:wool@4"
            ]
        },
        {
            "x": 5,
            "y": 12,
            "z": 0,
            "elements": [
                "minecraft:planks@4"
            ]
        },
        {
            "x": -2,
            "y": 6,
            "z": 1,
            "elements": [
                "minecraft:wool@4"
            ]
        },
        {
            "x": -1,
            "y": 8,
            "z": 2,
            "elements": [
                "minecraft:planks@4"
            ]
        },
        {
            "x": -1,
            "y": 6,
            "z": 1,
            "elements": [
                "minecraft:acacia_stairs@5"
            ]
        },
        {
            "x": 0,
            "y": 8,
            "z": 2,
            "elements": [
                "minecraft:wool@1"
            ]
        },
        {
            "x": 7,
            "y": 14,
            "z": 1,
            "elements": [
                "minecraft:wool@4"
            ]
        },
        {
            "x": 6,
            "y": 12,
            "z": 0,
            "elements": [
                "minecraft:acacia_stairs@5"
            ]
        },
        {
            "x": 0,
            "y": 6,
            "z": 1,
            "elements": [
                "minecraft:planks@4"
            ]
        },
        {
            "x": 1,
            "y": 6,
            "z": 1,
            "elements": [
                "minecraft:acacia_stairs@1"
            ]
        },
        {
            "x": -1,
            "y": 0,
            "z": 2,
            "elements": [
                "minecraft:wool@1"
            ]
        },
        {
            "x": 0,
            "y": 0,
            "z": 2,
            "elements": [
                "minecraft:wool@4"
            ]
        },
        {
            "x": 1,
            "y": 0,
            "z": 2,
            "elements": [
                "minecraft:wool@4"
            ]
        },
        {
            "x": -3,
            "y": 9,
            "z": 2,
            "elements": [
                "minecraft:acacia_stairs@4"
            ]
        },
        {
            "x": -2,
            "y": 9,
            "z": 2,
            "elements": [
                "minecraft:planks@4"
            ]
        },
        {
            "x": 4,
            "y": 13,
            "z": 0,
            "elements": [
                "minecraft:planks@4"
            ]
        },
        {
            "x": 6,
            "y": 15,
            "z": 1,
            "elements": [
                "minecraft:wool@4"
            ]
        },
        {
            "x": 5,
            "y": 13,
            "z": 0,
            "elements": [
                "minecraft:planks@4"
            ]
        },
        {
            "x": -2,
            "y": 7,
            "z": 1,
            "elements": [
                "minecraft:acacia_stairs@0"
            ]
        },
        {
            "x": -1,
            "y": 9,
            "z": 2,
            "elements": [
                "minecraft:acacia_stairs@1"
            ]
        },
        {
            "x": 7,
            "y": 15,
            "z": 1,
            "elements": [
                "minecraft:wool@11"
            ]
        },
        {
            "x": 6,
            "y": 13,
            "z": 0,
            "elements": [
                "minecraft:planks@4"
            ]
        },
        {
            "x": -2,
            "y": 5,
            "z": 0,
            "elements": [
                "minecraft:wool@4"
            ]
        },
        {
            "x": -1,
            "y": 7,
            "z": 1,
            "elements": [
                "minecraft:planks@4"
            ]
        },
        {
            "x": -1,
            "y": 5,
            "z": 0,
            "elements": [
                "minecraft:acacia_stairs@5"
            ]
        },
        {
            "x": 0,
            "y": 7,
            "z": 1,
            "elements": [
                "minecraft:planks@4"
            ]
        },
        {
            "x": 7,
            "y": 13,
            "z": 0,
            "elements": [
                "minecraft:acacia_stairs@5"
            ]
        },
        {
            "x": 1,
            "y": 7,
            "z": 1,
            "elements": [
                "minecraft:acacia_stairs@5"
            ]
        },
        {
            "x": 0,
            "y": 1,
            "z": 2,
            "elements": [
                "minecraft:oak_stairs@3"
            ]
        },
        {
            "x": -1,
            "y": -1,
            "z": 1,
            "elements": [
                "minecraft:stone_slab@9"
            ]
        },
        {
            "x": 0,
            "y": -1,
            "z": 1,
            "elements": [
                "minecraft:stone_slab@9"
            ]
        },
        {
            "x": 1,
            "y": -1,
            "z": 1,
            "elements": [
                "minecraft:stone_slab@9"
            ]
        },
        {
            "x": -4,
            "y": 10,
            "z": 2,
            "elements": [
                "minecraft:acacia_stairs@4"
            ]
        },
        {
            "x": -3,
            "y": 10,
            "z": 2,
            "elements": [
                "minecraft:planks@4"
            ]
        },
        {
            "x": -2,
            "y": 10,
            "z": 2,
            "elements": [
                "minecraft:acacia_stairs@1"
            ]
        },
        {
            "x": 4,
            "y": 14,
            "z": 0,
            "elements": [
                "minecraft:acacia_stairs@0"
            ]
        },
        {
            "x": 5,
            "y": 14,
            "z": 0,
            "elements": [
                "minecraft:planks@4"
            ]
        },
        {
            "x": -3,
            "y": 6,
            "z": 0,
            "elements": [
                "minecraft:wool@11"
            ]
        },
        {
            "x": -2,
            "y": 8,
            "z": 1,
            "elements": [
                "minecraft:acacia_stairs@4"
            ]
        },
        {
            "x": 6,
            "y": 14,
            "z": 0,
            "elements": [
                "minecraft:planks@4"
            ]
        },
        {
            "x": -2,
            "y": 6,
            "z": 0,
            "elements": [
                "minecraft:planks@4"
            ]
        },
        {
            "x": -1,
            "y": 8,
            "z": 1,
            "elements": [
                "minecraft:wool@4"
            ]
        },
        {
            "x": -1,
            "y": 6,
            "z": 0,
            "elements": [
                "minecraft:wool@4"
            ]
        },
        {
            "x": 0,
            "y": 8,
            "z": 1,
            "elements": [
                "minecraft:planks@4"
            ]
        },
        {
            "x": 7,
            "y": 14,
            "z": 0,
            "elements": [
                "minecraft:planks@4"
            ]
        },
        {
            "x": 1,
            "y": 8,
            "z": 1,
            "elements": [
                "minecraft:wool@1"
            ]
        },
        {
            "x": 8,
            "y": 14,
            "z": 0,
            "elements": [
                "minecraft:acacia_stairs@5"
            ]
        },
        {
            "x": 0,
            "y": 6,
            "z": 0,
            "elements": [
                "minecraft:acacia_stairs@6"
            ]
        },
        {
            "x": -1,
            "y": 0,
            "z": 1,
            "elements": [
                "modularmachinery:blockinputbus@6",
				"modularmachinery:blockinputbus@5",
				"modularmachinery:blockinputbus@4",
				"modularmachinery:blockinputbus@3",
				"modularmachinery:blockinputbus@2",
				"modularmachinery:blockinputbus@1",
				"modularmachinery:blockinputbus@0",
				"modularmachinery:blockoutputbus@6",
				"modularmachinery:blockoutputbus@5",
				"modularmachinery:blockoutputbus@4",
				"modularmachinery:blockoutputbus@3",
				"modularmachinery:blockoutputbus@2",
				"modularmachinery:blockoutputbus@1",
				"modularmachinery:blockoutputbus@0"
            ]
        },
        {
            "x": 0,
            "y": 0,
            "z": 1,
            "elements": [
                "minecraft:wool@4"
            ]
        },
        {
            "x": 1,
            "y": 0,
            "z": 1,
            "elements": [
                "modularmachinery:blockinputbus@6",
				"modularmachinery:blockinputbus@5",
				"modularmachinery:blockinputbus@4",
				"modularmachinery:blockinputbus@3",
				"modularmachinery:blockinputbus@2",
				"modularmachinery:blockinputbus@1",
				"modularmachinery:blockinputbus@0",
				"modularmachinery:blockoutputbus@6",
				"modularmachinery:blockoutputbus@5",
				"modularmachinery:blockoutputbus@4",
				"modularmachinery:blockoutputbus@3",
				"modularmachinery:blockoutputbus@2",
				"modularmachinery:blockoutputbus@1",
				"modularmachinery:blockoutputbus@0"
            ]
        },
        {
            "x": 0,
            "y": 8,
            "z": -1,
            "elements": [
                "minecraft:acacia_stairs@1"
            ]
        },
        {
            "x": -1,
            "y": 8,
            "z": -1,
            "elements": [
                "minecraft:acacia_stairs@0"
            ]
        },
        {
            "x": -5,
            "y": 11,
            "z": 2,
            "elements": [
                "minecraft:sandstone_stairs@4"
            ]
        },
        {
            "x": -4,
            "y": 11,
            "z": 2,
            "elements": [
                "minecraft:wool@4"
            ]
        },
        {
            "x": -3,
            "y": 11,
            "z": 2,
            "elements": [
                "minecraft:acacia_stairs@1"
            ]
        },
        {
            "x": -3,
            "y": 9,
            "z": 1,
            "elements": [
                "minecraft:acacia_stairs@4"
            ]
        },
        {
            "x": -3,
            "y": 7,
            "z": 0,
            "elements": [
                "minecraft:acacia_stairs@0"
            ]
        },
        {
            "x": -2,
            "y": 9,
            "z": 1,
            "elements": [
                "minecraft:sandstone@2"
            ]
        },
        {
            "x": 5,
            "y": 15,
            "z": 0,
            "elements": [
                "minecraft:acacia_stairs@0"
            ]
        },
        {
            "x": 6,
            "y": 15,
            "z": 0,
            "elements": [
                "minecraft:planks@4"
            ]
        },
        {
            "x": -2,
            "y": 7,
            "z": 0,
            "elements": [
                "minecraft:wool@4"
            ]
        },
        {
            "x": -1,
            "y": 9,
            "z": 1,
            "elements": [
                "minecraft:acacia_stairs@1"
            ]
        },
        {
            "x": 0,
            "y": 9,
            "z": 1,
            "elements": [
                "minecraft:wool@4"
            ]
        },
        {
            "x": 7,
            "y": 15,
            "z": 0,
            "elements": [
                "minecraft:wool@11"
            ]
        },
        {
            "x": -1,
            "y": 7,
            "z": 0,
            "elements": [
                "minecraft:planks@4"
            ]
        },
        {
            "x": 1,
            "y": 9,
            "z": 1,
            "elements": [
                "minecraft:planks@4"
            ]
        },
        {
            "x": 8,
            "y": 15,
            "z": 0,
            "elements": [
                "minecraft:wool@11"
            ]
        },
        {
            "x": 0,
            "y": 7,
            "z": 0,
            "elements": [
                "minecraft:planks@4"
            ]
        },
        {
            "x": 2,
            "y": 9,
            "z": 1,
            "elements": [
                "minecraft:acacia_stairs@5"
            ]
        },
        {
            "x": -1,
            "y": 1,
            "z": 1,
            "elements": [
                "minecraft:oak_stairs@0"
            ]
        },
        {
            "x": 0,
            "y": 1,
            "z": 1,
            "elements": [
                "minecraft:planks@4"
            ]
        },
        {
            "x": 1,
            "y": 1,
            "z": 1,
            "elements": [
                "minecraft:oak_stairs@1"
            ]
        },
        {
            "x": 0,
            "y": 7,
            "z": -1,
            "elements": [
                "minecraft:acacia_stairs@5"
            ]
        },
        {
            "x": 7,
            "y": 15,
            "z": -1,
            "elements": [
                "minecraft:wool@11"
            ]
        },
        {
            "x": -1,
            "y": 7,
            "z": -1,
            "elements": [
                "minecraft:planks@4"
            ]
        },
        {
            "x": 6,
            "y": 15,
            "z": -1,
            "elements": [
                "minecraft:wool@4"
            ]
        },
        {
            "x": -2,
            "y": 7,
            "z": -1,
            "elements": [
                "minecraft:acacia_stairs@0"
            ]
        },
        {
            "x": -5,
            "y": 12,
            "z": 2,
            "elements": [
                "minecraft:wool@4"
            ]
        },
        {
            "x": -4,
            "y": 12,
            "z": 2,
            "elements": [
                "minecraft:sandstone_stairs@1"
            ]
        },
        {
            "x": -3,
            "y": 10,
            "z": 1,
            "elements": [
                "minecraft:sandstone@2"
            ]
        },
        {
            "x": -2,
            "y": 10,
            "z": 1,
            "elements": [
                "minecraft:acacia_stairs@1"
            ]
        },
        {
            "x": 6,
            "y": 16,
            "z": 0,
            "elements": [
                "minecraft:acacia_stairs@0"
            ]
        },
        {
            "x": 7,
            "y": 16,
            "z": 0,
            "elements": [
                "minecraft:wool@11"
            ]
        },
        {
            "x": -1,
            "y": 8,
            "z": 0,
            "elements": [
                "minecraft:acacia_stairs@0"
            ]
        },
        {
            "x": 0,
            "y": 8,
            "z": 0,
            "elements": [
                "minecraft:wool@4"
            ]
        },
        {
            "x": 2,
            "y": 10,
            "z": 1,
            "elements": [
                "minecraft:planks@4"
            ]
        },
        {
            "x": 1,
            "y": 8,
            "z": 0,
            "elements": [
                "minecraft:acacia_stairs@5"
            ]
        },
        {
            "x": 3,
            "y": 10,
            "z": 1,
            "elements": [
                "minecraft:acacia_stairs@5"
            ]
        },
        {
            "x": 0,
            "y": 2,
            "z": 1,
            "elements": [
                "minecraft:planks@4"
            ]
        }
    ]}