{
	"registryname":"materialball_processor",
	"localizedname":"物质球处理机",
	"color":"000000",
    "parts": [
        {
            "x": 0,
            "y": 0,
            "z": 0,
            "elements": [
                "modularmachinery:blockcontroller@2"
            ]
        },
        {
            "x": -1,
            "y": 0,
            "z": 0,
            "elements": [
                "modularmachinery:blockinputbus@6",
				"modularmachinery:blockinputbus@5",
				"modularmachinery:blockinputbus@4",
				"modularmachinery:blockinputbus@3",
				"modularmachinery:blockinputbus@2",
				"modularmachinery:blockinputbus@1",
				"modularmachinery:blockinputbus@0",
				"modularmachinery:blockoutputbus@6",
				"modularmachinery:blockoutputbus@5",
				"modularmachinery:blockoutputbus@4",
				"modularmachinery:blockoutputbus@3",
				"modularmachinery:blockoutputbus@2",
				"modularmachinery:blockoutputbus@1",
				"modularmachinery:blockoutputbus@0",
				"modularmachinery:blockenergyinputhatch@7",
				"modularmachinery:blockenergyinputhatch@6",
				"modularmachinery:blockenergyinputhatch@5",
				"modularmachinery:blockenergyinputhatch@4",
				"modularmachinery:blockenergyinputhatch@3",
				"modularmachinery:blockenergyinputhatch@2",
				"modularmachinery:blockenergyinputhatch@1",
				"modularmachinery:blockenergyinputhatch@0",
				"modularmachinery:blockfluidinputhatch@7",
				"modularmachinery:blockfluidinputhatch@6",
				"modularmachinery:blockfluidinputhatch@5",
				"modularmachinery:blockfluidinputhatch@4",
				"modularmachinery:blockfluidinputhatch@3",
				"minecraft:concrete_powder@15"
            ]
        },
        {
            "x": 1,
            "y": 0,
            "z": 0,
            "elements": [
                "minecraft:concrete_powder@8"
            ]
        },
        {
            "x": -2,
            "y": 0,
            "z": 0,
            "elements": [
                "modularmachinery:blockinputbus@6",
				"modularmachinery:blockinputbus@5",
				"modularmachinery:blockinputbus@4",
				"modularmachinery:blockinputbus@3",
				"modularmachinery:blockinputbus@2",
				"modularmachinery:blockinputbus@1",
				"modularmachinery:blockinputbus@0",
				"modularmachinery:blockoutputbus@6",
				"modularmachinery:blockoutputbus@5",
				"modularmachinery:blockoutputbus@4",
				"modularmachinery:blockoutputbus@3",
				"modularmachinery:blockoutputbus@2",
				"modularmachinery:blockoutputbus@1",
				"modularmachinery:blockoutputbus@0",
				"modularmachinery:blockenergyinputhatch@7",
				"modularmachinery:blockenergyinputhatch@6",
				"modularmachinery:blockenergyinputhatch@5",
				"modularmachinery:blockenergyinputhatch@4",
				"modularmachinery:blockenergyinputhatch@3",
				"modularmachinery:blockenergyinputhatch@2",
				"modularmachinery:blockenergyinputhatch@1",
				"modularmachinery:blockenergyinputhatch@0",
				"modularmachinery:blockfluidinputhatch@7",
				"modularmachinery:blockfluidinputhatch@6",
				"modularmachinery:blockfluidinputhatch@5",
				"modularmachinery:blockfluidinputhatch@4",
				"modularmachinery:blockfluidinputhatch@3",
				"minecraft:concrete_powder@15"
            ]
        },
        {
            "x": 2,
            "y": 0,
            "z": 0,
            "elements": [
                "extrautils2:decorativesolid@3"
            ]
        },
        {
            "x": -3,
            "y": 0,
            "z": 0,
            "elements": [
                "modularmachinery:blockinputbus@6",
				"modularmachinery:blockinputbus@5",
				"modularmachinery:blockinputbus@4",
				"modularmachinery:blockinputbus@3",
				"modularmachinery:blockinputbus@2",
				"modularmachinery:blockinputbus@1",
				"modularmachinery:blockinputbus@0",
				"modularmachinery:blockoutputbus@6",
				"modularmachinery:blockoutputbus@5",
				"modularmachinery:blockoutputbus@4",
				"modularmachinery:blockoutputbus@3",
				"modularmachinery:blockoutputbus@2",
				"modularmachinery:blockoutputbus@1",
				"modularmachinery:blockoutputbus@0",
				"modularmachinery:blockenergyinputhatch@7",
				"modularmachinery:blockenergyinputhatch@6",
				"modularmachinery:blockenergyinputhatch@5",
				"modularmachinery:blockenergyinputhatch@4",
				"modularmachinery:blockenergyinputhatch@3",
				"modularmachinery:blockenergyinputhatch@2",
				"modularmachinery:blockenergyinputhatch@1",
				"modularmachinery:blockenergyinputhatch@0",
				"modularmachinery:blockfluidinputhatch@7",
				"modularmachinery:blockfluidinputhatch@6",
				"modularmachinery:blockfluidinputhatch@5",
				"modularmachinery:blockfluidinputhatch@4",
				"modularmachinery:blockfluidinputhatch@3",
				"minecraft:concrete_powder@15"
            ]
        },
        {
            "x": -4,
            "y": 0,
            "z": 0,
            "elements": [
                "modularmachinery:blockinputbus@6",
				"modularmachinery:blockinputbus@5",
				"modularmachinery:blockinputbus@4",
				"modularmachinery:blockinputbus@3",
				"modularmachinery:blockinputbus@2",
				"modularmachinery:blockinputbus@1",
				"modularmachinery:blockinputbus@0",
				"modularmachinery:blockoutputbus@6",
				"modularmachinery:blockoutputbus@5",
				"modularmachinery:blockoutputbus@4",
				"modularmachinery:blockoutputbus@3",
				"modularmachinery:blockoutputbus@2",
				"modularmachinery:blockoutputbus@1",
				"modularmachinery:blockoutputbus@0",
				"modularmachinery:blockenergyinputhatch@7",
				"modularmachinery:blockenergyinputhatch@6",
				"modularmachinery:blockenergyinputhatch@5",
				"modularmachinery:blockenergyinputhatch@4",
				"modularmachinery:blockenergyinputhatch@3",
				"modularmachinery:blockenergyinputhatch@2",
				"modularmachinery:blockenergyinputhatch@1",
				"modularmachinery:blockenergyinputhatch@0",
				"modularmachinery:blockfluidinputhatch@7",
				"modularmachinery:blockfluidinputhatch@6",
				"modularmachinery:blockfluidinputhatch@5",
				"modularmachinery:blockfluidinputhatch@4",
				"modularmachinery:blockfluidinputhatch@3",
				"minecraft:concrete_powder@15"
            ]
        },
        {
            "x": -5,
            "y": 0,
            "z": 0,
            "elements": [
                "modularmachinery:blockinputbus@6",
				"modularmachinery:blockinputbus@5",
				"modularmachinery:blockinputbus@4",
				"modularmachinery:blockinputbus@3",
				"modularmachinery:blockinputbus@2",
				"modularmachinery:blockinputbus@1",
				"modularmachinery:blockinputbus@0",
				"modularmachinery:blockoutputbus@6",
				"modularmachinery:blockoutputbus@5",
				"modularmachinery:blockoutputbus@4",
				"modularmachinery:blockoutputbus@3",
				"modularmachinery:blockoutputbus@2",
				"modularmachinery:blockoutputbus@1",
				"modularmachinery:blockoutputbus@0",
				"modularmachinery:blockenergyinputhatch@7",
				"modularmachinery:blockenergyinputhatch@6",
				"modularmachinery:blockenergyinputhatch@5",
				"modularmachinery:blockenergyinputhatch@4",
				"modularmachinery:blockenergyinputhatch@3",
				"modularmachinery:blockenergyinputhatch@2",
				"modularmachinery:blockenergyinputhatch@1",
				"modularmachinery:blockenergyinputhatch@0",
				"modularmachinery:blockfluidinputhatch@7",
				"modularmachinery:blockfluidinputhatch@6",
				"modularmachinery:blockfluidinputhatch@5",
				"modularmachinery:blockfluidinputhatch@4",
				"modularmachinery:blockfluidinputhatch@3",
				"minecraft:concrete_powder@15"
            ]
        },
        {
            "x": -6,
            "y": 0,
            "z": 0,
            "elements": [
                "modularmachinery:blockinputbus@6",
				"modularmachinery:blockinputbus@5",
				"modularmachinery:blockinputbus@4",
				"modularmachinery:blockinputbus@3",
				"modularmachinery:blockinputbus@2",
				"modularmachinery:blockinputbus@1",
				"modularmachinery:blockinputbus@0",
				"modularmachinery:blockoutputbus@6",
				"modularmachinery:blockoutputbus@5",
				"modularmachinery:blockoutputbus@4",
				"modularmachinery:blockoutputbus@3",
				"modularmachinery:blockoutputbus@2",
				"modularmachinery:blockoutputbus@1",
				"modularmachinery:blockoutputbus@0",
				"modularmachinery:blockenergyinputhatch@7",
				"modularmachinery:blockenergyinputhatch@6",
				"modularmachinery:blockenergyinputhatch@5",
				"modularmachinery:blockenergyinputhatch@4",
				"modularmachinery:blockenergyinputhatch@3",
				"modularmachinery:blockenergyinputhatch@2",
				"modularmachinery:blockenergyinputhatch@1",
				"modularmachinery:blockenergyinputhatch@0",
				"modularmachinery:blockfluidinputhatch@7",
				"modularmachinery:blockfluidinputhatch@6",
				"modularmachinery:blockfluidinputhatch@5",
				"modularmachinery:blockfluidinputhatch@4",
				"modularmachinery:blockfluidinputhatch@3",
				"minecraft:concrete_powder@15"
            ]
        },
        {
            "x": -7,
            "y": 0,
            "z": 0,
            "elements": [
                "modularmachinery:blockinputbus@6",
				"modularmachinery:blockinputbus@5",
				"modularmachinery:blockinputbus@4",
				"modularmachinery:blockinputbus@3",
				"modularmachinery:blockinputbus@2",
				"modularmachinery:blockinputbus@1",
				"modularmachinery:blockinputbus@0",
				"modularmachinery:blockoutputbus@6",
				"modularmachinery:blockoutputbus@5",
				"modularmachinery:blockoutputbus@4",
				"modularmachinery:blockoutputbus@3",
				"modularmachinery:blockoutputbus@2",
				"modularmachinery:blockoutputbus@1",
				"modularmachinery:blockoutputbus@0",
				"modularmachinery:blockenergyinputhatch@7",
				"modularmachinery:blockenergyinputhatch@6",
				"modularmachinery:blockenergyinputhatch@5",
				"modularmachinery:blockenergyinputhatch@4",
				"modularmachinery:blockenergyinputhatch@3",
				"modularmachinery:blockenergyinputhatch@2",
				"modularmachinery:blockenergyinputhatch@1",
				"modularmachinery:blockenergyinputhatch@0",
				"modularmachinery:blockfluidinputhatch@7",
				"modularmachinery:blockfluidinputhatch@6",
				"modularmachinery:blockfluidinputhatch@5",
				"modularmachinery:blockfluidinputhatch@4",
				"modularmachinery:blockfluidinputhatch@3",
				"minecraft:concrete_powder@15"
            ]
        },
        {
            "x": -8,
            "y": 0,
            "z": 0,
            "elements": [
                "modularmachinery:blockinputbus@6",
				"modularmachinery:blockinputbus@5",
				"modularmachinery:blockinputbus@4",
				"modularmachinery:blockinputbus@3",
				"modularmachinery:blockinputbus@2",
				"modularmachinery:blockinputbus@1",
				"modularmachinery:blockinputbus@0",
				"modularmachinery:blockoutputbus@6",
				"modularmachinery:blockoutputbus@5",
				"modularmachinery:blockoutputbus@4",
				"modularmachinery:blockoutputbus@3",
				"modularmachinery:blockoutputbus@2",
				"modularmachinery:blockoutputbus@1",
				"modularmachinery:blockoutputbus@0",
				"modularmachinery:blockenergyinputhatch@7",
				"modularmachinery:blockenergyinputhatch@6",
				"modularmachinery:blockenergyinputhatch@5",
				"modularmachinery:blockenergyinputhatch@4",
				"modularmachinery:blockenergyinputhatch@3",
				"modularmachinery:blockenergyinputhatch@2",
				"modularmachinery:blockenergyinputhatch@1",
				"modularmachinery:blockenergyinputhatch@0",
				"modularmachinery:blockfluidinputhatch@7",
				"modularmachinery:blockfluidinputhatch@6",
				"modularmachinery:blockfluidinputhatch@5",
				"modularmachinery:blockfluidinputhatch@4",
				"modularmachinery:blockfluidinputhatch@3",
				"minecraft:concrete_powder@15"
            ]
        },
        {
            "x": -9,
            "y": 0,
            "z": 0,
            "elements": [
                "modularmachinery:blockinputbus@6",
				"modularmachinery:blockinputbus@5",
				"modularmachinery:blockinputbus@4",
				"modularmachinery:blockinputbus@3",
				"modularmachinery:blockinputbus@2",
				"modularmachinery:blockinputbus@1",
				"modularmachinery:blockinputbus@0",
				"modularmachinery:blockoutputbus@6",
				"modularmachinery:blockoutputbus@5",
				"modularmachinery:blockoutputbus@4",
				"modularmachinery:blockoutputbus@3",
				"modularmachinery:blockoutputbus@2",
				"modularmachinery:blockoutputbus@1",
				"modularmachinery:blockoutputbus@0",
				"modularmachinery:blockenergyinputhatch@7",
				"modularmachinery:blockenergyinputhatch@6",
				"modularmachinery:blockenergyinputhatch@5",
				"modularmachinery:blockenergyinputhatch@4",
				"modularmachinery:blockenergyinputhatch@3",
				"modularmachinery:blockenergyinputhatch@2",
				"modularmachinery:blockenergyinputhatch@1",
				"modularmachinery:blockenergyinputhatch@0",
				"modularmachinery:blockfluidinputhatch@7",
				"modularmachinery:blockfluidinputhatch@6",
				"modularmachinery:blockfluidinputhatch@5",
				"modularmachinery:blockfluidinputhatch@4",
				"modularmachinery:blockfluidinputhatch@3",
				"minecraft:concrete_powder@15"
            ]
        },
        {
            "x": -10,
            "y": 0,
            "z": 0,
            "elements": [
                "modularmachinery:blockinputbus@6",
				"modularmachinery:blockinputbus@5",
				"modularmachinery:blockinputbus@4",
				"modularmachinery:blockinputbus@3",
				"modularmachinery:blockinputbus@2",
				"modularmachinery:blockinputbus@1",
				"modularmachinery:blockinputbus@0",
				"modularmachinery:blockoutputbus@6",
				"modularmachinery:blockoutputbus@5",
				"modularmachinery:blockoutputbus@4",
				"modularmachinery:blockoutputbus@3",
				"modularmachinery:blockoutputbus@2",
				"modularmachinery:blockoutputbus@1",
				"modularmachinery:blockoutputbus@0",
				"modularmachinery:blockenergyinputhatch@7",
				"modularmachinery:blockenergyinputhatch@6",
				"modularmachinery:blockenergyinputhatch@5",
				"modularmachinery:blockenergyinputhatch@4",
				"modularmachinery:blockenergyinputhatch@3",
				"modularmachinery:blockenergyinputhatch@2",
				"modularmachinery:blockenergyinputhatch@1",
				"modularmachinery:blockenergyinputhatch@0",
				"modularmachinery:blockfluidinputhatch@7",
				"modularmachinery:blockfluidinputhatch@6",
				"modularmachinery:blockfluidinputhatch@5",
				"modularmachinery:blockfluidinputhatch@4",
				"modularmachinery:blockfluidinputhatch@3",
				"minecraft:concrete_powder@15"
            ]
        },
        {
            "x": -11,
            "y": 0,
            "z": 0,
            "elements": [
                "modularmachinery:blockinputbus@6",
				"modularmachinery:blockinputbus@5",
				"modularmachinery:blockinputbus@4",
				"modularmachinery:blockinputbus@3",
				"modularmachinery:blockinputbus@2",
				"modularmachinery:blockinputbus@1",
				"modularmachinery:blockinputbus@0",
				"modularmachinery:blockoutputbus@6",
				"modularmachinery:blockoutputbus@5",
				"modularmachinery:blockoutputbus@4",
				"modularmachinery:blockoutputbus@3",
				"modularmachinery:blockoutputbus@2",
				"modularmachinery:blockoutputbus@1",
				"modularmachinery:blockoutputbus@0",
				"modularmachinery:blockenergyinputhatch@7",
				"modularmachinery:blockenergyinputhatch@6",
				"modularmachinery:blockenergyinputhatch@5",
				"modularmachinery:blockenergyinputhatch@4",
				"modularmachinery:blockenergyinputhatch@3",
				"modularmachinery:blockenergyinputhatch@2",
				"modularmachinery:blockenergyinputhatch@1",
				"modularmachinery:blockenergyinputhatch@0",
				"modularmachinery:blockfluidinputhatch@7",
				"modularmachinery:blockfluidinputhatch@6",
				"modularmachinery:blockfluidinputhatch@5",
				"modularmachinery:blockfluidinputhatch@4",
				"modularmachinery:blockfluidinputhatch@3",
				"minecraft:concrete_powder@15"
            ]
        },
        {
            "x": -12,
            "y": 0,
            "z": 0,
            "elements": [
                "minecraft:concrete_powder@8"
            ]
        },
        {
            "x": -13,
            "y": 0,
            "z": 0,
            "elements": [
                "extrautils2:decorativesolid@3"
            ]
        },
        {
            "x": -13,
            "y": 9,
            "z": 4,
            "elements": [
                "extrautils2:decorativesolid@1"
            ]
        },
        {
            "x": -12,
            "y": 9,
            "z": 4,
            "elements": [
                "chisel:antiblock@0"
            ]
        },
        {
            "x": -13,
            "y": 1,
            "z": 0,
            "elements": [
                "extrautils2:decorativesolid@3"
            ]
        },
        {
            "x": -12,
            "y": 1,
            "z": 0,
            "elements": [
                "minecraft:concrete_powder@8"
            ]
        },
        {
            "x": -11,
            "y": 1,
            "z": 0,
            "elements": [
                "minecraft:concrete_powder@15"
            ]
        },
        {
            "x": -10,
            "y": 1,
            "z": 0,
            "elements": [
                "minecraft:concrete_powder@15"
            ]
        },
        {
            "x": -9,
            "y": 1,
            "z": 0,
            "elements": [
                "minecraft:concrete_powder@15"
            ]
        },
        {
            "x": -8,
            "y": 1,
            "z": 0,
            "elements": [
                "minecraft:concrete_powder@15"
            ]
        },
        {
            "x": -7,
            "y": 1,
            "z": 0,
            "elements": [
                "minecraft:concrete_powder@15"
            ]
        },
        {
            "x": -6,
            "y": 1,
            "z": 0,
            "elements": [
                "minecraft:concrete_powder@15"
            ]
        },
        {
            "x": -5,
            "y": 1,
            "z": 0,
            "elements": [
                "minecraft:concrete_powder@15"
            ]
        },
        {
            "x": -4,
            "y": 1,
            "z": 0,
            "elements": [
                "minecraft:concrete_powder@15"
            ]
        },
        {
            "x": 1,
            "y": 9,
            "z": 4,
            "elements": [
                "chisel:antiblock@0"
            ]
        },
        {
            "x": 2,
            "y": -1,
            "z": 0,
            "elements": [
                "extrautils2:decorativesolid@3"
            ]
        },
        {
            "x": -3,
            "y": 1,
            "z": 0,
            "elements": [
                "minecraft:concrete_powder@15"
            ]
        },
        {
            "x": 1,
            "y": -1,
            "z": 0,
            "elements": [
                "extrautils2:decorativesolid@3"
            ]
        },
        {
            "x": -2,
            "y": 1,
            "z": 0,
            "elements": [
                "minecraft:concrete_powder@15"
            ]
        },
        {
            "x": 2,
            "y": 9,
            "z": 4,
            "elements": [
                "extrautils2:decorativesolid@1"
            ]
        },
        {
            "x": 0,
            "y": -1,
            "z": 0,
            "elements": [
                "extrautils2:decorativesolid@3"
            ]
        },
        {
            "x": -1,
            "y": 1,
            "z": 0,
            "elements": [
                "minecraft:concrete_powder@15"
            ]
        },
        {
            "x": 0,
            "y": 1,
            "z": 0,
            "elements": [
                "minecraft:concrete_powder@15"
            ]
        },
        {
            "x": -1,
            "y": -1,
            "z": 0,
            "elements": [
                "extrautils2:decorativesolid@3"
            ]
        },
        {
            "x": 1,
            "y": 1,
            "z": 0,
            "elements": [
                "minecraft:concrete_powder@8"
            ]
        },
        {
            "x": -2,
            "y": -1,
            "z": 0,
            "elements": [
                "extrautils2:decorativesolid@3"
            ]
        },
        {
            "x": 2,
            "y": 1,
            "z": 0,
            "elements": [
                "extrautils2:decorativesolid@3"
            ]
        },
        {
            "x": -3,
            "y": -1,
            "z": 0,
            "elements": [
                "extrautils2:decorativesolid@3"
            ]
        },
        {
            "x": -4,
            "y": -1,
            "z": 0,
            "elements": [
                "extrautils2:decorativesolid@3"
            ]
        },
        {
            "x": -5,
            "y": -1,
            "z": 0,
            "elements": [
                "extrautils2:decorativesolid@3"
            ]
        },
        {
            "x": -6,
            "y": -1,
            "z": 0,
            "elements": [
                "extrautils2:decorativesolid@3"
            ]
        },
        {
            "x": -7,
            "y": -1,
            "z": 0,
            "elements": [
                "extrautils2:decorativesolid@3"
            ]
        },
        {
            "x": -8,
            "y": -1,
            "z": 0,
            "elements": [
                "extrautils2:decorativesolid@3"
            ]
        },
        {
            "x": -9,
            "y": -1,
            "z": 0,
            "elements": [
                "extrautils2:decorativesolid@3"
            ]
        },
        {
            "x": -10,
            "y": -1,
            "z": 0,
            "elements": [
                "extrautils2:decorativesolid@3"
            ]
        },
        {
            "x": -11,
            "y": -1,
            "z": 0,
            "elements": [
                "extrautils2:decorativesolid@3"
            ]
        },
        {
            "x": -12,
            "y": -1,
            "z": 0,
            "elements": [
                "extrautils2:decorativesolid@3"
            ]
        },
        {
            "x": -13,
            "y": -1,
            "z": 0,
            "elements": [
                "extrautils2:decorativesolid@3"
            ]
        },
        {
            "x": -13,
            "y": 10,
            "z": 4,
            "elements": [
                "extrautils2:decorativesolid@1"
            ]
        },
        {
            "x": -12,
            "y": 10,
            "z": 4,
            "elements": [
                "chisel:antiblock@0"
            ]
        },
        {
            "x": -13,
            "y": 2,
            "z": 0,
            "elements": [
                "extrautils2:decorativesolid@3"
            ]
        },
        {
            "x": -12,
            "y": 2,
            "z": 0,
            "elements": [
                "minecraft:concrete_powder@8"
            ]
        },
        {
            "x": -11,
            "y": 2,
            "z": 0,
            "elements": [
                "minecraft:concrete_powder@15"
            ]
        },
        {
            "x": -10,
            "y": 2,
            "z": 0,
            "elements": [
                "minecraft:concrete_powder@15"
            ]
        },
        {
            "x": -9,
            "y": 2,
            "z": 0,
            "elements": [
                "minecraft:concrete_powder@15"
            ]
        },
        {
            "x": -8,
            "y": 2,
            "z": 0,
            "elements": [
                "minecraft:concrete_powder@15"
            ]
        },
        {
            "x": -7,
            "y": 2,
            "z": 0,
            "elements": [
                "minecraft:concrete_powder@15"
            ]
        },
        {
            "x": -6,
            "y": 2,
            "z": 0,
            "elements": [
                "minecraft:concrete_powder@15"
            ]
        },
        {
            "x": -5,
            "y": 2,
            "z": 0,
            "elements": [
                "minecraft:concrete_powder@15"
            ]
        },
        {
            "x": -4,
            "y": 2,
            "z": 0,
            "elements": [
                "minecraft:concrete_powder@15"
            ]
        },
        {
            "x": 1,
            "y": 10,
            "z": 4,
            "elements": [
                "chisel:antiblock@0"
            ]
        },
        {
            "x": -3,
            "y": 2,
            "z": 0,
            "elements": [
                "minecraft:concrete_powder@15"
            ]
        },
        {
            "x": -2,
            "y": 2,
            "z": 0,
            "elements": [
                "minecraft:concrete_powder@15"
            ]
        },
        {
            "x": 2,
            "y": 10,
            "z": 4,
            "elements": [
                "extrautils2:decorativesolid@1"
            ]
        },
        {
            "x": -1,
            "y": 2,
            "z": 0,
            "elements": [
                "minecraft:concrete_powder@15"
            ]
        },
        {
            "x": 0,
            "y": 2,
            "z": 0,
            "elements": [
                "minecraft:concrete_powder@15"
            ]
        },
        {
            "x": 1,
            "y": 2,
            "z": 0,
            "elements": [
                "minecraft:concrete_powder@8"
            ]
        },
        {
            "x": 2,
            "y": 2,
            "z": 0,
            "elements": [
                "extrautils2:decorativesolid@3"
            ]
        },
        {
            "x": -13,
            "y": 11,
            "z": 4,
            "elements": [
                "extrautils2:decorativesolid@1"
            ]
        },
        {
            "x": -12,
            "y": 11,
            "z": 4,
            "elements": [
                "chisel:antiblock@0"
            ]
        },
        {
            "x": -13,
            "y": 3,
            "z": 0,
            "elements": [
                "extrautils2:decorativesolid@3"
            ]
        },
        {
            "x": -12,
            "y": 3,
            "z": 0,
            "elements": [
                "minecraft:concrete_powder@8"
            ]
        },
        {
            "x": -11,
            "y": 3,
            "z": 0,
            "elements": [
                "chisel:stonebrick2@9"
            ]
        },
        {
            "x": -10,
            "y": 3,
            "z": 0,
            "elements": [
                "minecraft:concrete_powder@7"
            ]
        },
        {
            "x": -9,
            "y": 3,
            "z": 0,
            "elements": [
                "minecraft:concrete_powder@15"
            ]
        },
        {
            "x": -8,
            "y": 3,
            "z": 0,
            "elements": [
                "minecraft:concrete_powder@15"
            ]
        },
        {
            "x": -7,
            "y": 3,
            "z": 0,
            "elements": [
                "minecraft:concrete_powder@15"
            ]
        },
        {
            "x": -6,
            "y": 3,
            "z": 0,
            "elements": [
                "minecraft:concrete_powder@15"
            ]
        },
        {
            "x": -5,
            "y": 3,
            "z": 0,
            "elements": [
                "minecraft:concrete_powder@15"
            ]
        },
        {
            "x": -4,
            "y": 3,
            "z": 0,
            "elements": [
                "minecraft:concrete_powder@15"
            ]
        },
        {
            "x": 1,
            "y": 11,
            "z": 4,
            "elements": [
                "chisel:antiblock@0"
            ]
        },
        {
            "x": -3,
            "y": 3,
            "z": 0,
            "elements": [
                "minecraft:concrete_powder@15"
            ]
        },
        {
            "x": -2,
            "y": 3,
            "z": 0,
            "elements": [
                "minecraft:concrete_powder@15"
            ]
        },
        {
            "x": 2,
            "y": 11,
            "z": 4,
            "elements": [
                "extrautils2:decorativesolid@1"
            ]
        },
        {
            "x": -1,
            "y": 3,
            "z": 0,
            "elements": [
                "minecraft:concrete_powder@7"
            ]
        },
        {
            "x": 0,
            "y": 3,
            "z": 0,
            "elements": [
                "chisel:stonebrick2@9"
            ]
        },
        {
            "x": 1,
            "y": 3,
            "z": 0,
            "elements": [
                "minecraft:concrete_powder@8"
            ]
        },
        {
            "x": 2,
            "y": 3,
            "z": 0,
            "elements": [
                "extrautils2:decorativesolid@3"
            ]
        },
        {
            "x": -13,
            "y": 12,
            "z": 4,
            "elements": [
                "extrautils2:decorativesolid@1"
            ]
        },
        {
            "x": -12,
            "y": 12,
            "z": 4,
            "elements": [
                "chisel:antiblock@1"
            ]
        },
        {
            "x": -11,
            "y": 12,
            "z": 4,
            "elements": [
                "chisel:antiblock@0"
            ]
        },
        {
            "x": -10,
            "y": 12,
            "z": 4,
            "elements": [
                "chisel:antiblock@0"
            ]
        },
        {
            "x": -13,
            "y": 4,
            "z": 0,
            "elements": [
                "extrautils2:decorativesolid@3"
            ]
        },
        {
            "x": -9,
            "y": 12,
            "z": 4,
            "elements": [
                "chisel:antiblock@0"
            ]
        },
        {
            "x": -12,
            "y": 4,
            "z": 0,
            "elements": [
                "minecraft:concrete_powder@8"
            ]
        },
        {
            "x": -8,
            "y": 12,
            "z": 4,
            "elements": [
                "chisel:antiblock@0"
            ]
        },
        {
            "x": -11,
            "y": 4,
            "z": 0,
            "elements": [
                "chisel:stonebrick2@9"
            ]
        },
        {
            "x": -7,
            "y": 12,
            "z": 4,
            "elements": [
                "chisel:antiblock@0"
            ]
        },
        {
            "x": -10,
            "y": 4,
            "z": 0,
            "elements": [
                "chisel:stonebrick2@9"
            ]
        },
        {
            "x": -6,
            "y": 12,
            "z": 4,
            "elements": [
                "chisel:antiblock@0"
            ]
        },
        {
            "x": -9,
            "y": 4,
            "z": 0,
            "elements": [
                "minecraft:concrete_powder@7"
            ]
        },
        {
            "x": -5,
            "y": 12,
            "z": 4,
            "elements": [
                "chisel:antiblock@0"
            ]
        },
        {
            "x": -8,
            "y": 4,
            "z": 0,
            "elements": [
                "minecraft:concrete_powder@7"
            ]
        },
        {
            "x": -4,
            "y": 12,
            "z": 4,
            "elements": [
                "chisel:antiblock@0"
            ]
        },
        {
            "x": -7,
            "y": 4,
            "z": 0,
            "elements": [
                "minecraft:concrete_powder@15"
            ]
        },
        {
            "x": -3,
            "y": 12,
            "z": 4,
            "elements": [
                "chisel:antiblock@0"
            ]
        },
        {
            "x": -6,
            "y": 4,
            "z": 0,
            "elements": [
                "minecraft:concrete_powder@15"
            ]
        },
        {
            "x": -2,
            "y": 12,
            "z": 4,
            "elements": [
                "chisel:antiblock@0"
            ]
        },
        {
            "x": -5,
            "y": 4,
            "z": 0,
            "elements": [
                "minecraft:concrete_powder@15"
            ]
        },
        {
            "x": -1,
            "y": 12,
            "z": 4,
            "elements": [
                "chisel:antiblock@0"
            ]
        },
        {
            "x": 0,
            "y": 12,
            "z": 4,
            "elements": [
                "chisel:antiblock@0"
            ]
        },
        {
            "x": -4,
            "y": 4,
            "z": 0,
            "elements": [
                "minecraft:concrete_powder@15"
            ]
        },
        {
            "x": 1,
            "y": 12,
            "z": 4,
            "elements": [
                "chisel:antiblock@1"
            ]
        },
        {
            "x": -3,
            "y": 4,
            "z": 0,
            "elements": [
                "minecraft:concrete_powder@7"
            ]
        },
        {
            "x": -2,
            "y": 4,
            "z": 0,
            "elements": [
                "minecraft:concrete_powder@7"
            ]
        },
        {
            "x": 2,
            "y": 12,
            "z": 4,
            "elements": [
                "extrautils2:decorativesolid@1"
            ]
        },
        {
            "x": -1,
            "y": 4,
            "z": 0,
            "elements": [
                "chisel:stonebrick2@9"
            ]
        },
        {
            "x": 0,
            "y": 4,
            "z": 0,
            "elements": [
                "chisel:stonebrick2@9"
            ]
        },
        {
            "x": 1,
            "y": 4,
            "z": 0,
            "elements": [
                "minecraft:concrete_powder@8"
            ]
        },
        {
            "x": 2,
            "y": 4,
            "z": 0,
            "elements": [
                "extrautils2:decorativesolid@3"
            ]
        },
        {
            "x": -13,
            "y": 13,
            "z": 4,
            "elements": [
                "minecraft:concrete_powder@8"
            ]
        },
        {
            "x": -12,
            "y": 13,
            "z": 4,

            "elements": [
                "minecraft:furnace@5"
            ]
        },
        {
            "x": -11,
            "y": 13,
            "z": 4,

            "elements": [
                "minecraft:furnace@5"
            ]
        },
        {
            "x": -10,
            "y": 13,
            "z": 4,

            "elements": [
                "minecraft:furnace@5"
            ]
        },
        {
            "x": -13,
            "y": 5,
            "z": 0,
            "elements": [
                "extrautils2:decorativesolid@3"
            ]
        },
        {
            "x": -9,
            "y": 13,
            "z": 4,

            "elements": [
                "minecraft:furnace@5"
            ]
        },
        {
            "x": -12,
            "y": 5,
            "z": 0,
            "elements": [
                "minecraft:concrete_powder@8"
            ]
        },
        {
            "x": -8,
            "y": 13,
            "z": 4,

            "elements": [
                "minecraft:furnace@5"
            ]
        },
        {
            "x": -11,
            "y": 5,
            "z": 0,
            "elements": [
                "chisel:stonebrick2@9"
            ]
        },
        {
            "x": -7,
            "y": 13,
            "z": 4,

            "elements": [
                "minecraft:furnace@5"
            ]
        },
        {
            "x": -10,
            "y": 5,
            "z": 0,
            "elements": [
                "chisel:stonebrick2@9"
            ]
        },
        {
            "x": -6,
            "y": 13,
            "z": 4,

            "elements": [
                "minecraft:furnace@5"
            ]
        },
        {
            "x": -9,
            "y": 5,
            "z": 0,
            "elements": [
                "chisel:stonebrick2@9"
            ]
        },
        {
            "x": -5,
            "y": 13,
            "z": 4,

            "elements": [
                "minecraft:furnace@5"
            ]
        },
        {
            "x": -8,
            "y": 5,
            "z": 0,
            "elements": [
                "minecraft:concrete_powder@7"
            ]
        },
        {
            "x": -4,
            "y": 13,
            "z": 4,

            "elements": [
                "minecraft:furnace@5"
            ]
        },
        {
            "x": -7,
            "y": 5,
            "z": 0,
            "elements": [
                "minecraft:concrete_powder@7"
            ]
        },
        {
            "x": -3,
            "y": 13,
            "z": 4,

            "elements": [
                "minecraft:furnace@5"
            ]
        },
        {
            "x": -6,
            "y": 5,
            "z": 0,
            "elements": [
                "minecraft:concrete_powder@7"
            ]
        },
        {
            "x": -2,
            "y": 13,
            "z": 4,

            "elements": [
                "minecraft:furnace@5"
            ]
        },
        {
            "x": -5,
            "y": 5,
            "z": 0,
            "elements": [
                "minecraft:concrete_powder@7"
            ]
        },
        {
            "x": -1,
            "y": 13,
            "z": 4,

            "elements": [
                "minecraft:furnace@5"
            ]
        },
        {
            "x": 0,
            "y": 13,
            "z": 4,

            "elements": [
                "minecraft:furnace@5"
            ]
        },
        {
            "x": -4,
            "y": 5,
            "z": 0,
            "elements": [
                "minecraft:concrete_powder@7"
            ]
        },
        {
            "x": 1,
            "y": 13,
            "z": 4,

            "elements": [
                "minecraft:furnace@4"
            ]
        },
        {
            "x": -3,
            "y": 5,
            "z": 0,
            "elements": [
                "minecraft:concrete_powder@7"
            ]
        },
        {
            "x": -2,
            "y": 5,
            "z": 0,
            "elements": [
                "chisel:stonebrick2@9"
            ]
        },
        {
            "x": 2,
            "y": 13,
            "z": 4,
            "elements": [
                "minecraft:concrete_powder@8"
            ]
        },
        {
            "x": -1,
            "y": 5,
            "z": 0,
            "elements": [
                "chisel:stonebrick2@9"
            ]
        },
        {
            "x": 0,
            "y": 5,
            "z": 0,
            "elements": [
                "chisel:stonebrick2@9"
            ]
        },
        {
            "x": 1,
            "y": 5,
            "z": 0,
            "elements": [
                "minecraft:concrete_powder@8"
            ]
        },
        {
            "x": 2,
            "y": 5,
            "z": 0,
            "elements": [
                "extrautils2:decorativesolid@3"
            ]
        },
        {
            "x": -13,
            "y": -1,
            "z": 13,
            "elements": [
                "extrautils2:decorativesolid@3"
            ]
        },
        {
            "x": -12,
            "y": -1,
            "z": 13,
            "elements": [
                "extrautils2:decorativesolid@1"
            ]
        },
        {
            "x": -11,
            "y": -1,
            "z": 13,
            "elements": [
                "extrautils2:decorativesolid@1"
            ]
        },
        {
            "x": -10,
            "y": -1,
            "z": 13,
            "elements": [
                "extrautils2:decorativesolid@1"
            ]
        },
        {
            "x": -9,
            "y": -1,
            "z": 13,
            "elements": [
                "extrautils2:decorativesolid@1"
            ]
        },
        {
            "x": -8,
            "y": -1,
            "z": 13,
            "elements": [
                "extrautils2:decorativesolid@1"
            ]
        },
        {
            "x": -7,
            "y": -1,
            "z": 13,
            "elements": [
                "extrautils2:decorativesolid@1"
            ]
        },
        {
            "x": -6,
            "y": -1,
            "z": 13,
            "elements": [
                "extrautils2:decorativesolid@1"
            ]
        },
        {
            "x": -5,
            "y": -1,
            "z": 13,
            "elements": [
                "extrautils2:decorativesolid@1"
            ]
        },
        {
            "x": -13,
            "y": 14,
            "z": 4,
            "elements": [
                "extrautils2:decorativesolid@3"
            ]
        },
        {
            "x": -12,
            "y": 14,
            "z": 4,
            "elements": [
                "extrautils2:decorativesolid@1"
            ]
        },
        {
            "x": -4,
            "y": -1,
            "z": 13,
            "elements": [
                "extrautils2:decorativesolid@1"
            ]
        },
        {
            "x": -11,
            "y": 14,
            "z": 4,
            "elements": [
                "extrautils2:decorativesolid@1"
            ]
        },
        {
            "x": -3,
            "y": -1,
            "z": 13,
            "elements": [
                "extrautils2:decorativesolid@1"
            ]
        },
        {
            "x": -10,
            "y": 14,
            "z": 4,
            "elements": [
                "extrautils2:decorativesolid@1"
            ]
        },
        {
            "x": -2,
            "y": -1,
            "z": 13,
            "elements": [
                "extrautils2:decorativesolid@1"
            ]
        },
        {
            "x": -13,
            "y": 6,
            "z": 0,
            "elements": [
                "extrautils2:decorativesolid@3"
            ]
        },
        {
            "x": -9,
            "y": 14,
            "z": 4,
            "elements": [
                "extrautils2:decorativesolid@1"
            ]
        },
        {
            "x": -1,
            "y": -1,
            "z": 13,
            "elements": [
                "extrautils2:decorativesolid@1"
            ]
        },
        {
            "x": 0,
            "y": -1,
            "z": 13,
            "elements": [
                "extrautils2:decorativesolid@1"
            ]
        },
        {
            "x": -12,
            "y": 6,
            "z": 0,
            "elements": [
                "minecraft:concrete_powder@8"
            ]
        },
        {
            "x": -8,
            "y": 14,
            "z": 4,
            "elements": [
                "extrautils2:decorativesolid@1"
            ]
        },
        {
            "x": 1,
            "y": -1,
            "z": 13,
            "elements": [
                "extrautils2:decorativesolid@1"
            ]
        },
        {
            "x": -11,
            "y": 6,
            "z": 0,
            "elements": [
                "chisel:stonebrick2@9"
            ]
        },
        {
            "x": -7,
            "y": 14,
            "z": 4,
            "elements": [
                "extrautils2:decorativesolid@1"
            ]
        },
        {
            "x": -10,
            "y": 6,
            "z": 0,
            "elements": [
                "chisel:stonebrick2@9"
            ]
        },
        {
            "x": -6,
            "y": 14,
            "z": 4,
            "elements": [
                "extrautils2:decorativesolid@1"
            ]
        },
        {
            "x": 2,
            "y": -1,
            "z": 13,
            "elements": [
                "extrautils2:decorativesolid@3"
            ]
        },
        {
            "x": -9,
            "y": 6,
            "z": 0,
            "elements": [
                "chisel:stonebrick2@9"
            ]
        },
        {
            "x": -5,
            "y": 14,
            "z": 4,
            "elements": [
                "extrautils2:decorativesolid@1"
            ]
        },
        {
            "x": -8,
            "y": 6,
            "z": 0,
            "elements": [
                "chisel:stonebrick2@9"
            ]
        },
        {
            "x": -4,
            "y": 14,
            "z": 4,
            "elements": [
                "extrautils2:decorativesolid@1"
            ]
        },
        {
            "x": -7,
            "y": 6,
            "z": 0,
            "elements": [
                "chisel:stonebrick2@9"
            ]
        },
        {
            "x": -3,
            "y": 14,
            "z": 4,
            "elements": [
                "extrautils2:decorativesolid@1"
            ]
        },
        {
            "x": -6,
            "y": 6,
            "z": 0,
            "elements": [
                "chisel:stonebrick2@9"
            ]
        },
        {
            "x": -2,
            "y": 14,
            "z": 4,
            "elements": [
                "extrautils2:decorativesolid@1"
            ]
        },
        {
            "x": -5,
            "y": 6,
            "z": 0,
            "elements": [
                "chisel:stonebrick2@9"
            ]
        },
        {
            "x": -1,
            "y": 14,
            "z": 4,
            "elements": [
                "extrautils2:decorativesolid@1"
            ]
        },
        {
            "x": 0,
            "y": 14,
            "z": 4,
            "elements": [
                "extrautils2:decorativesolid@1"
            ]
        },
        {
            "x": -4,
            "y": 6,
            "z": 0,
            "elements": [
                "chisel:stonebrick2@9"
            ]
        },
        {
            "x": 1,
            "y": 14,
            "z": 4,
            "elements": [
                "extrautils2:decorativesolid@1"
            ]
        },
        {
            "x": -3,
            "y": 6,
            "z": 0,
            "elements": [
                "chisel:stonebrick2@9"
            ]
        },
        {
            "x": -2,
            "y": 6,
            "z": 0,
            "elements": [
                "chisel:stonebrick2@9"
            ]
        },
        {
            "x": 2,
            "y": 14,
            "z": 4,
            "elements": [
                "extrautils2:decorativesolid@3"
            ]
        },
        {
            "x": -1,
            "y": 6,
            "z": 0,
            "elements": [
                "chisel:stonebrick2@9"
            ]
        },
        {
            "x": 0,
            "y": 6,
            "z": 0,
            "elements": [
                "chisel:stonebrick2@9"
            ]
        },
        {
            "x": 1,
            "y": 6,
            "z": 0,
            "elements": [
                "minecraft:concrete_powder@8"
            ]
        },
        {
            "x": 2,
            "y": 6,
            "z": 0,
            "elements": [
                "extrautils2:decorativesolid@3"
            ]
        },
        {
            "x": -13,
            "y": 0,
            "z": 13,
            "elements": [
                "minecraft:concrete_powder@8"
            ]
        },
        {
            "x": -12,
            "y": 0,
            "z": 13,

            "elements": [
                "minecraft:furnace@4"
            ]
        },
        {
            "x": -11,
            "y": 0,
            "z": 13,

            "elements": [
                "minecraft:furnace@5"
            ]
        },
        {
            "x": -10,
            "y": 0,
            "z": 13,

            "elements": [
                "minecraft:furnace@5"
            ]
        },
        {
            "x": -9,
            "y": 0,
            "z": 13,

            "elements": [
                "minecraft:furnace@5"
            ]
        },
        {
            "x": -8,
            "y": 0,
            "z": 13,

            "elements": [
                "minecraft:furnace@5"
            ]
        },
        {
            "x": -7,
            "y": 0,
            "z": 13,

            "elements": [
                "minecraft:furnace@5"
            ]
        },
        {
            "x": -6,
            "y": 0,
            "z": 13,

            "elements": [
                "minecraft:furnace@5"
            ]
        },
        {
            "x": -5,
            "y": 0,
            "z": 13,

            "elements": [
                "minecraft:furnace@5"
            ]
        },
        {
            "x": -4,
            "y": 0,
            "z": 13,

            "elements": [
                "minecraft:furnace@5"
            ]
        },
        {
            "x": -3,
            "y": 0,
            "z": 13,

            "elements": [
                "minecraft:furnace@5"
            ]
        },
        {
            "x": -2,
            "y": 0,
            "z": 13,

            "elements": [
                "minecraft:furnace@5"
            ]
        },
        {
            "x": -1,
            "y": 0,
            "z": 13,

            "elements": [
                "minecraft:furnace@5"
            ]
        },
        {
            "x": -13,
            "y": 7,
            "z": 0,
            "elements": [
                "extrautils2:decorativesolid@3"
            ]
        },
        {
            "x": 0,
            "y": 0,
            "z": 13,

            "elements": [
                "minecraft:furnace@5"
            ]
        },
        {
            "x": -12,
            "y": 7,
            "z": 0,
            "elements": [
                "minecraft:concrete_powder@8"
            ]
        },
        {
            "x": 1,
            "y": 0,
            "z": 13,

            "elements": [
                "minecraft:furnace@4"
            ]
        },
        {
            "x": -11,
            "y": 7,
            "z": 0,
            "elements": [
                "minecraft:concrete_powder@8"
            ]
        },
        {
            "x": -10,
            "y": 7,
            "z": 0,
            "elements": [
                "chisel:stonebrick2@9"
            ]
        },
        {
            "x": 2,
            "y": 0,
            "z": 13,
            "elements": [
                "minecraft:concrete_powder@8"
            ]
        },
        {
            "x": -9,
            "y": 7,
            "z": 0,
            "elements": [
                "minecraft:concrete_powder@7"
            ]
        },
        {
            "x": -8,
            "y": 7,
            "z": 0,
            "elements": [
                "minecraft:concrete_powder@7"
            ]
        },
        {
            "x": -7,
            "y": 7,
            "z": 0,
            "elements": [
                "minecraft:concrete_powder@7"
            ]
        },
        {
            "x": -6,
            "y": 7,
            "z": 0,
            "elements": [
                "minecraft:concrete_powder@7"
            ]
        },
        {
            "x": -5,
            "y": 7,
            "z": 0,
            "elements": [
                "minecraft:concrete_powder@7"
            ]
        },
        {
            "x": -4,
            "y": 7,
            "z": 0,
            "elements": [
                "minecraft:concrete_powder@7"
            ]
        },
        {
            "x": -3,
            "y": 7,
            "z": 0,
            "elements": [
                "minecraft:concrete_powder@7"
            ]
        },
        {
            "x": -2,
            "y": 7,
            "z": 0,
            "elements": [
                "minecraft:concrete_powder@7"
            ]
        },
        {
            "x": -1,
            "y": 7,
            "z": 0,
            "elements": [
                "minecraft:concrete_powder@8"
            ]
        },
        {
            "x": 0,
            "y": 7,
            "z": 0,
            "elements": [
                "minecraft:concrete_powder@8"
            ]
        },
        {
            "x": 1,
            "y": 7,
            "z": 0,
            "elements": [
                "minecraft:concrete_powder@8"
            ]
        },
        {
            "x": 2,
            "y": 7,
            "z": 0,
            "elements": [
                "extrautils2:decorativesolid@3"
            ]
        },
        {
            "x": -13,
            "y": 1,
            "z": 13,
            "elements": [
                "chisel:stonebrick2@9"
            ]
        },
        {
            "x": -12,
            "y": 1,
            "z": 13,
            "elements": [
                "chisel:antiblock@1"
            ]
        },
        {
            "x": -11,
            "y": 1,
            "z": 13,
            "elements": [
                "chisel:antiblock@0"
            ]
        },
        {
            "x": -10,
            "y": 1,
            "z": 13,
            "elements": [
                "chisel:antiblock@0"
            ]
        },
        {
            "x": -9,
            "y": 1,
            "z": 13,
            "elements": [
                "chisel:antiblock@0"
            ]
        },
        {
            "x": -8,
            "y": 1,
            "z": 13,
            "elements": [
                "chisel:antiblock@0"
            ]
        },
        {
            "x": -7,
            "y": 1,
            "z": 13,
            "elements": [
                "chisel:antiblock@0"
            ]
        },
        {
            "x": -6,
            "y": 1,
            "z": 13,
            "elements": [
                "chisel:antiblock@0"
            ]
        },
        {
            "x": -5,
            "y": 1,
            "z": 13,
            "elements": [
                "chisel:antiblock@0"
            ]
        },
        {
            "x": -4,
            "y": 1,
            "z": 13,
            "elements": [
                "chisel:antiblock@0"
            ]
        },
        {
            "x": -3,
            "y": 1,
            "z": 13,
            "elements": [
                "chisel:antiblock@0"
            ]
        },
        {
            "x": -2,
            "y": 1,
            "z": 13,
            "elements": [
                "chisel:antiblock@0"
            ]
        },
        {
            "x": -1,
            "y": 1,
            "z": 13,
            "elements": [
                "chisel:antiblock@0"
            ]
        },
        {
            "x": -13,
            "y": 8,
            "z": 0,
            "elements": [
                "extrautils2:decorativesolid@3"
            ]
        },
        {
            "x": 0,
            "y": 1,
            "z": 13,
            "elements": [
                "chisel:antiblock@0"
            ]
        },
        {
            "x": -12,
            "y": 8,
            "z": 0,
            "elements": [
                "minecraft:concrete_powder@8"
            ]
        },
        {
            "x": 1,
            "y": 1,
            "z": 13,
            "elements": [
                "chisel:antiblock@1"
            ]
        },
        {
            "x": -11,
            "y": 8,
            "z": 0,
            "elements": [
                "minecraft:concrete_powder@8"
            ]
        },
        {
            "x": -10,
            "y": 8,
            "z": 0,
            "elements": [
                "minecraft:concrete_powder@7"
            ]
        },
        {
            "x": 2,
            "y": 1,
            "z": 13,
            "elements": [
                "chisel:stonebrick2@9"
            ]
        },
        {
            "x": -9,
            "y": 8,
            "z": 0,
            "elements": [
                "minecraft:concrete_powder@8"
            ]
        },
        {
            "x": -8,
            "y": 8,
            "z": 0,
            "elements": [
                "minecraft:concrete_powder@8"
            ]
        },
        {
            "x": -7,
            "y": 8,
            "z": 0,
            "elements": [
                "minecraft:concrete_powder@8"
            ]
        },
        {
            "x": -6,
            "y": 8,
            "z": 0,
            "elements": [
                "minecraft:concrete_powder@8"
            ]
        },
        {
            "x": -5,
            "y": 8,
            "z": 0,
            "elements": [
                "minecraft:concrete_powder@8"
            ]
        },
        {
            "x": -4,
            "y": 8,
            "z": 0,
            "elements": [
                "minecraft:concrete_powder@8"
            ]
        },
        {
            "x": -3,
            "y": 8,
            "z": 0,
            "elements": [
                "minecraft:concrete_powder@8"
            ]
        },
        {
            "x": -2,
            "y": 8,
            "z": 0,
            "elements": [
                "minecraft:concrete_powder@8"
            ]
        },
        {
            "x": -1,
            "y": 8,
            "z": 0,
            "elements": [
                "minecraft:concrete_powder@7"
            ]
        },
        {
            "x": 0,
            "y": 8,
            "z": 0,
            "elements": [
                "minecraft:concrete_powder@8"
            ]
        },
        {
            "x": 1,
            "y": 8,
            "z": 0,
            "elements": [
                "minecraft:concrete_powder@8"
            ]
        },
        {
            "x": 2,
            "y": 8,
            "z": 0,
            "elements": [
                "extrautils2:decorativesolid@3"
            ]
        },
        {
            "x": -13,
            "y": 2,
            "z": 13,
            "elements": [
                "chisel:stonebrick2@9"
            ]
        },
        {
            "x": -12,
            "y": 2,
            "z": 13,
            "elements": [
                "chisel:antiblock@0"
            ]
        },
        {
            "x": -13,
            "y": 9,
            "z": 0,
            "elements": [
                "extrautils2:decorativesolid@3"
            ]
        },
        {
            "x": -12,
            "y": 9,
            "z": 0,
            "elements": [
                "minecraft:concrete_powder@8"
            ]
        },
        {
            "x": 1,
            "y": 2,
            "z": 13,
            "elements": [
                "chisel:antiblock@0"
            ]
        },
        {
            "x": -11,
            "y": 9,
            "z": 0,
            "elements": [
                "minecraft:concrete_powder@8"
            ]
        },
        {
            "x": -10,
            "y": 9,
            "z": 0,
            "elements": [
                "minecraft:concrete_powder@7"
            ]
        },
        {
            "x": 2,
            "y": 2,
            "z": 13,
            "elements": [
                "chisel:stonebrick2@9"
            ]
        },
        {
            "x": -9,
            "y": 9,
            "z": 0,
            "elements": [
                "minecraft:concrete_powder@15"
            ]
        },
        {
            "x": -8,
            "y": 9,
            "z": 0,
            "elements": [
                "minecraft:concrete_powder@15"
            ]
        },
        {
            "x": -7,
            "y": 9,
            "z": 0,
            "elements": [
                "minecraft:concrete_powder@15"
            ]
        },
        {
            "x": -6,
            "y": 9,
            "z": 0,
            "elements": [
                "minecraft:concrete_powder@15"
            ]
        },
        {
            "x": -5,
            "y": 9,
            "z": 0,
            "elements": [
                "minecraft:concrete_powder@15"
            ]
        },
        {
            "x": -4,
            "y": 9,
            "z": 0,
            "elements": [
                "minecraft:concrete_powder@15"
            ]
        },
        {
            "x": -3,
            "y": 9,
            "z": 0,
            "elements": [
                "minecraft:concrete_powder@15"
            ]
        },
        {
            "x": -2,
            "y": 9,
            "z": 0,
            "elements": [
                "minecraft:concrete_powder@15"
            ]
        },
        {
            "x": -1,
            "y": 9,
            "z": 0,
            "elements": [
                "minecraft:concrete_powder@7"
            ]
        },
        {
            "x": 0,
            "y": 9,
            "z": 0,
            "elements": [
                "minecraft:concrete_powder@8"
            ]
        },
        {
            "x": 1,
            "y": 9,
            "z": 0,
            "elements": [
                "minecraft:concrete_powder@8"
            ]
        },
        {
            "x": 2,
            "y": 9,
            "z": 0,
            "elements": [
                "extrautils2:decorativesolid@3"
            ]
        },
        {
            "x": -13,
            "y": 3,
            "z": 13,
            "elements": [
                "chisel:stonebrick2@9"
            ]
        },
        {
            "x": -12,
            "y": 3,
            "z": 13,
            "elements": [
                "chisel:antiblock@0"
            ]
        },
        {
            "x": -13,
            "y": 10,
            "z": 0,
            "elements": [
                "extrautils2:decorativesolid@3"
            ]
        },
        {
            "x": -12,
            "y": 10,
            "z": 0,
            "elements": [
                "minecraft:concrete_powder@8"
            ]
        },
        {
            "x": 1,
            "y": 3,
            "z": 13,
            "elements": [
                "chisel:antiblock@0"
            ]
        },
        {
            "x": -11,
            "y": 10,
            "z": 0,
            "elements": [
                "minecraft:concrete_powder@8"
            ]
        },
        {
            "x": -10,
            "y": 10,
            "z": 0,
            "elements": [
                "minecraft:concrete_powder@7"
            ]
        },
        {
            "x": 2,
            "y": 3,
            "z": 13,
            "elements": [
                "chisel:stonebrick2@9"
            ]
        },
        {
            "x": -9,
            "y": 10,
            "z": 0,
            "elements": [
                "minecraft:concrete_powder@15"
            ]
        },
        {
            "x": -8,
            "y": 10,
            "z": 0,
            "elements": [
                "minecraft:concrete_powder@15"
            ]
        },
        {
            "x": -7,
            "y": 10,
            "z": 0,
            "elements": [
                "minecraft:concrete_powder@15"
            ]
        },
        {
            "x": -6,
            "y": 10,
            "z": 0,
            "elements": [
                "minecraft:concrete_powder@15"
            ]
        },
        {
            "x": -5,
            "y": 10,
            "z": 0,
            "elements": [
                "minecraft:concrete_powder@15"
            ]
        },
        {
            "x": -4,
            "y": 10,
            "z": 0,
            "elements": [
                "minecraft:concrete_powder@15"
            ]
        },
        {
            "x": -3,
            "y": 10,
            "z": 0,
            "elements": [
                "minecraft:concrete_powder@15"
            ]
        },
        {
            "x": -2,
            "y": 10,
            "z": 0,
            "elements": [
                "minecraft:concrete_powder@15"
            ]
        },
        {
            "x": -1,
            "y": 10,
            "z": 0,
            "elements": [
                "minecraft:concrete_powder@7"
            ]
        },
        {
            "x": 0,
            "y": 10,
            "z": 0,
            "elements": [
                "minecraft:concrete_powder@8"
            ]
        },
        {
            "x": 1,
            "y": 10,
            "z": 0,
            "elements": [
                "minecraft:concrete_powder@8"
            ]
        },
        {
            "x": 2,
            "y": 10,
            "z": 0,
            "elements": [
                "extrautils2:decorativesolid@3"
            ]
        },
        {
            "x": -13,
            "y": 4,
            "z": 13,
            "elements": [
                "chisel:stonebrick2@9"
            ]
        },
        {
            "x": -12,
            "y": 4,
            "z": 13,
            "elements": [
                "chisel:antiblock@0"
            ]
        },
        {
            "x": -13,
            "y": 11,
            "z": 0,
            "elements": [
                "extrautils2:decorativesolid@3"
            ]
        },
        {
            "x": -12,
            "y": 11,
            "z": 0,
            "elements": [
                "minecraft:concrete_powder@8"
            ]
        },
        {
            "x": 1,
            "y": 4,
            "z": 13,
            "elements": [
                "chisel:antiblock@0"
            ]
        },
        {
            "x": -11,
            "y": 11,
            "z": 0,
            "elements": [
                "minecraft:concrete_powder@8"
            ]
        },
        {
            "x": -10,
            "y": 11,
            "z": 0,
            "elements": [
                "minecraft:concrete_powder@8"
            ]
        },
        {
            "x": 2,
            "y": 4,
            "z": 13,
            "elements": [
                "chisel:stonebrick2@9"
            ]
        },
        {
            "x": -9,
            "y": 11,
            "z": 0,
            "elements": [
                "minecraft:concrete_powder@7"
            ]
        },
        {
            "x": -8,
            "y": 11,
            "z": 0,
            "elements": [
                "minecraft:concrete_powder@15"
            ]
        },
        {
            "x": -7,
            "y": 11,
            "z": 0,
            "elements": [
                "minecraft:concrete_powder@15"
            ]
        },
        {
            "x": -6,
            "y": 11,
            "z": 0,
            "elements": [
                "minecraft:concrete_powder@15"
            ]
        },
        {
            "x": -5,
            "y": 11,
            "z": 0,
            "elements": [
                "minecraft:concrete_powder@15"
            ]
        },
        {
            "x": -4,
            "y": 11,
            "z": 0,
            "elements": [
                "minecraft:concrete_powder@15"
            ]
        },
        {
            "x": -3,
            "y": 11,
            "z": 0,
            "elements": [
                "minecraft:concrete_powder@15"
            ]
        },
        {
            "x": -2,
            "y": 11,
            "z": 0,
            "elements": [
                "minecraft:concrete_powder@7"
            ]
        },
        {
            "x": -1,
            "y": 11,
            "z": 0,
            "elements": [
                "minecraft:concrete_powder@8"
            ]
        },
        {
            "x": 0,
            "y": 11,
            "z": 0,
            "elements": [
                "minecraft:concrete_powder@8"
            ]
        },
        {
            "x": 1,
            "y": 11,
            "z": 0,
            "elements": [
                "minecraft:concrete_powder@8"
            ]
        },
        {
            "x": 2,
            "y": 11,
            "z": 0,
            "elements": [
                "extrautils2:decorativesolid@3"
            ]
        },
        {
            "x": -13,
            "y": 5,
            "z": 13,
            "elements": [
                "chisel:stonebrick2@9"
            ]
        },
        {
            "x": -12,
            "y": 5,
            "z": 13,
            "elements": [
                "chisel:antiblock@0"
            ]
        },
        {
            "x": -13,
            "y": 12,
            "z": 0,
            "elements": [
                "extrautils2:decorativesolid@3"
            ]
        },
        {
            "x": -12,
            "y": 12,
            "z": 0,
            "elements": [
                "minecraft:concrete_powder@8"
            ]
        },
        {
            "x": 1,
            "y": 5,
            "z": 13,
            "elements": [
                "chisel:antiblock@0"
            ]
        },
        {
            "x": -11,
            "y": 12,
            "z": 0,
            "elements": [
                "minecraft:concrete_powder@8"
            ]
        },
        {
            "x": -10,
            "y": 12,
            "z": 0,
            "elements": [
                "minecraft:concrete_powder@8"
            ]
        },
        {
            "x": 2,
            "y": 5,
            "z": 13,
            "elements": [
                "chisel:stonebrick2@9"
            ]
        },
        {
            "x": -9,
            "y": 12,
            "z": 0,
            "elements": [
                "minecraft:concrete_powder@8"
            ]
        },
        {
            "x": -8,
            "y": 12,
            "z": 0,
            "elements": [
                "minecraft:concrete_powder@15"
            ]
        },
        {
            "x": -7,
            "y": 12,
            "z": 0,
            "elements": [
                "minecraft:concrete_powder@15"
            ]
        },
        {
            "x": -6,
            "y": 12,
            "z": 0,
            "elements": [
                "minecraft:concrete_powder@15"
            ]
        },
        {
            "x": -5,
            "y": 12,
            "z": 0,
            "elements": [
                "minecraft:concrete_powder@15"
            ]
        },
        {
            "x": -4,
            "y": 12,
            "z": 0,
            "elements": [
                "minecraft:concrete_powder@15"
            ]
        },
        {
            "x": -3,
            "y": 12,
            "z": 0,
            "elements": [
                "minecraft:concrete_powder@15"
            ]
        },
        {
            "x": -2,
            "y": 12,
            "z": 0,
            "elements": [
                "minecraft:concrete_powder@8"
            ]
        },
        {
            "x": -1,
            "y": 12,
            "z": 0,
            "elements": [
                "minecraft:concrete_powder@8"
            ]
        },
        {
            "x": 0,
            "y": 12,
            "z": 0,
            "elements": [
                "minecraft:concrete_powder@8"
            ]
        },
        {
            "x": 1,
            "y": 12,
            "z": 0,
            "elements": [
                "minecraft:concrete_powder@8"
            ]
        },
        {
            "x": 2,
            "y": 12,
            "z": 0,
            "elements": [
                "extrautils2:decorativesolid@3"
            ]
        },
        {
            "x": -13,
            "y": 6,
            "z": 13,
            "elements": [
                "extrautils2:decorativesolid@1"
            ]
        },
        {
            "x": -12,
            "y": 6,
            "z": 13,
            "elements": [
                "chisel:antiblock@0"
            ]
        },
        {
            "x": -13,
            "y": 13,
            "z": 0,
            "elements": [
                "extrautils2:decorativesolid@3"
            ]
        },
        {
            "x": -12,
            "y": 13,
            "z": 0,
            "elements": [
                "minecraft:concrete_powder@8"
            ]
        },
        {
            "x": 1,
            "y": 6,
            "z": 13,
            "elements": [
                "chisel:antiblock@0"
            ]
        },
        {
            "x": -11,
            "y": 13,
            "z": 0,
            "elements": [
                "minecraft:concrete_powder@8"
            ]
        },
        {
            "x": -10,
            "y": 13,
            "z": 0,
            "elements": [
                "minecraft:concrete_powder@8"
            ]
        },
        {
            "x": 2,
            "y": 6,
            "z": 13,
            "elements": [
                "extrautils2:decorativesolid@1"
            ]
        },
        {
            "x": -9,
            "y": 13,
            "z": 0,
            "elements": [
                "minecraft:concrete_powder@8"
            ]
        },
        {
            "x": -8,
            "y": 13,
            "z": 0,
            "elements": [
                "minecraft:concrete_powder@8"
            ]
        },
        {
            "x": -7,
            "y": 13,
            "z": 0,
            "elements": [
                "minecraft:concrete_powder@8"
            ]
        },
        {
            "x": -6,
            "y": 13,
            "z": 0,
            "elements": [
                "minecraft:concrete_powder@8"
            ]
        },
        {
            "x": -5,
            "y": 13,
            "z": 0,
            "elements": [
                "minecraft:concrete_powder@8"
            ]
        },
        {
            "x": -4,
            "y": 13,
            "z": 0,
            "elements": [
                "minecraft:concrete_powder@8"
            ]
        },
        {
            "x": -3,
            "y": 13,
            "z": 0,
            "elements": [
                "minecraft:concrete_powder@8"
            ]
        },
        {
            "x": -2,
            "y": 13,
            "z": 0,
            "elements": [
                "minecraft:concrete_powder@8"
            ]
        },
        {
            "x": -1,
            "y": 13,
            "z": 0,
            "elements": [
                "minecraft:concrete_powder@8"
            ]
        },
        {
            "x": 0,
            "y": 13,
            "z": 0,
            "elements": [
                "minecraft:concrete_powder@8"
            ]
        },
        {
            "x": 1,
            "y": 13,
            "z": 0,
            "elements": [
                "minecraft:concrete_powder@8"
            ]
        },
        {
            "x": 2,
            "y": 13,
            "z": 0,
            "elements": [
                "extrautils2:decorativesolid@3"
            ]
        },
        {
            "x": -13,
            "y": 7,
            "z": 13,
            "elements": [
                "extrautils2:decorativesolid@1"
            ]
        },
        {
            "x": -12,
            "y": 7,
            "z": 13,
            "elements": [
                "chisel:antiblock@0"
            ]
        },
        {
            "x": -13,
            "y": -1,
            "z": 9,
            "elements": [
                "extrautils2:decorativesolid@3"
            ]
        },
        {
            "x": -12,
            "y": -1,
            "z": 9,
            "elements": [
                "extrautils2:decorativesolid@1"
            ]
        },
        {
            "x": -11,
            "y": -1,
            "z": 9,
            "elements": [
                "extrautils2:decorativesolid@1"
            ]
        },
        {
            "x": -10,
            "y": -1,
            "z": 9,
            "elements": [
                "extrautils2:decorativesolid@1"
            ]
        },
        {
            "x": -9,
            "y": -1,
            "z": 9,
            "elements": [
                "extrautils2:decorativesolid@1"
            ]
        },
        {
            "x": -8,
            "y": -1,
            "z": 9,
            "elements": [
                "extrautils2:decorativesolid@1"
            ]
        },
        {
            "x": -7,
            "y": -1,
            "z": 9,
            "elements": [
                "extrautils2:decorativesolid@1"
            ]
        },
        {
            "x": -6,
            "y": -1,
            "z": 9,
            "elements": [
                "extrautils2:decorativesolid@1"
            ]
        },
        {
            "x": -5,
            "y": -1,
            "z": 9,
            "elements": [
                "extrautils2:decorativesolid@1"
            ]
        },
        {
            "x": -13,
            "y": 14,
            "z": 0,
            "elements": [
                "extrautils2:decorativesolid@3"
            ]
        },
        {
            "x": -12,
            "y": 14,
            "z": 0,
            "elements": [
                "extrautils2:decorativesolid@3"
            ]
        },
        {
            "x": -4,
            "y": -1,
            "z": 9,
            "elements": [
                "extrautils2:decorativesolid@1"
            ]
        },
        {
            "x": 1,
            "y": 7,
            "z": 13,
            "elements": [
                "chisel:antiblock@0"
            ]
        },
        {
            "x": -11,
            "y": 14,
            "z": 0,
            "elements": [
                "extrautils2:decorativesolid@3"
            ]
        },
        {
            "x": -3,
            "y": -1,
            "z": 9,
            "elements": [
                "extrautils2:decorativesolid@1"
            ]
        },
        {
            "x": -10,
            "y": 14,
            "z": 0,
            "elements": [
                "extrautils2:decorativesolid@3"
            ]
        },
        {
            "x": -2,
            "y": -1,
            "z": 9,
            "elements": [
                "extrautils2:decorativesolid@1"
            ]
        },
        {
            "x": 2,
            "y": 7,
            "z": 13,
            "elements": [
                "extrautils2:decorativesolid@1"
            ]
        },
        {
            "x": -9,
            "y": 14,
            "z": 0,
            "elements": [
                "extrautils2:decorativesolid@3"
            ]
        },
        {
            "x": -1,
            "y": -1,
            "z": 9,
            "elements": [
                "extrautils2:decorativesolid@1"
            ]
        },
        {
            "x": 0,
            "y": -1,
            "z": 9,
            "elements": [
                "extrautils2:decorativesolid@1"
            ]
        },
        {
            "x": -8,
            "y": 14,
            "z": 0,
            "elements": [
                "extrautils2:decorativesolid@3"
            ]
        },
        {
            "x": 1,
            "y": -1,
            "z": 9,
            "elements": [
                "extrautils2:decorativesolid@1"
            ]
        },
        {
            "x": -7,
            "y": 14,
            "z": 0,
            "elements": [
                "extrautils2:decorativesolid@3"
            ]
        },
        {
            "x": -6,
            "y": 14,
            "z": 0,
            "elements": [
                "extrautils2:decorativesolid@3"
            ]
        },
        {
            "x": 2,
            "y": -1,
            "z": 9,
            "elements": [
                "extrautils2:decorativesolid@3"
            ]
        },
        {
            "x": -5,
            "y": 14,
            "z": 0,
            "elements": [
                "extrautils2:decorativesolid@3"
            ]
        },
        {
            "x": -4,
            "y": 14,
            "z": 0,
            "elements": [
                "extrautils2:decorativesolid@3"
            ]
        },
        {
            "x": -3,
            "y": 14,
            "z": 0,
            "elements": [
                "extrautils2:decorativesolid@3"
            ]
        },
        {
            "x": -2,
            "y": 14,
            "z": 0,
            "elements": [
                "extrautils2:decorativesolid@3"
            ]
        },
        {
            "x": -1,
            "y": 14,
            "z": 0,
            "elements": [
                "extrautils2:decorativesolid@3"
            ]
        },
        {
            "x": 0,
            "y": 14,
            "z": 0,
            "elements": [
                "extrautils2:decorativesolid@3"
            ]
        },
        {
            "x": 1,
            "y": 14,
            "z": 0,
            "elements": [
                "extrautils2:decorativesolid@3"
            ]
        },
        {
            "x": 2,
            "y": 14,
            "z": 0,
            "elements": [
                "extrautils2:decorativesolid@3"
            ]
        },
        {
            "x": -13,
            "y": 8,
            "z": 13,
            "elements": [
                "extrautils2:decorativesolid@1"
            ]
        },
        {
            "x": -12,
            "y": 8,
            "z": 13,
            "elements": [
                "chisel:antiblock@0"
            ]
        },
        {
            "x": -13,
            "y": 0,
            "z": 9,
            "elements": [
                "minecraft:concrete_powder@8"
            ]
        },
        {
            "x": -12,
            "y": 0,
            "z": 9,

            "elements": [
                "minecraft:furnace@4"
            ]
        },
        {
            "x": -11,
            "y": 0,
            "z": 9,

            "elements": [
                "minecraft:furnace@5"
            ]
        },
        {
            "x": -10,
            "y": 0,
            "z": 9,

            "elements": [
                "minecraft:furnace@5"
            ]
        },
        {
            "x": -9,
            "y": 0,
            "z": 9,

            "elements": [
                "minecraft:furnace@5"
            ]
        },
        {
            "x": -8,
            "y": 0,
            "z": 9,

            "elements": [
                "minecraft:furnace@5"
            ]
        },
        {
            "x": -7,
            "y": 0,
            "z": 9,

            "elements": [
                "minecraft:furnace@5"
            ]
        },
        {
            "x": -6,
            "y": 0,
            "z": 9,

            "elements": [
                "minecraft:furnace@5"
            ]
        },
        {
            "x": -5,
            "y": 0,
            "z": 9,

            "elements": [
                "minecraft:furnace@5"
            ]
        },
        {
            "x": -4,
            "y": 0,
            "z": 9,

            "elements": [
                "minecraft:furnace@5"
            ]
        },
        {
            "x": 1,
            "y": 8,
            "z": 13,
            "elements": [
                "chisel:antiblock@0"
            ]
        },
        {
            "x": -3,
            "y": 0,
            "z": 9,

            "elements": [
                "minecraft:furnace@5"
            ]
        },
        {
            "x": -2,
            "y": 0,
            "z": 9,

            "elements": [
                "minecraft:furnace@5"
            ]
        },
        {
            "x": 2,
            "y": 8,
            "z": 13,
            "elements": [
                "extrautils2:decorativesolid@1"
            ]
        },
        {
            "x": -1,
            "y": 0,
            "z": 9,

            "elements": [
                "minecraft:furnace@5"
            ]
        },
        {
            "x": 0,
            "y": 0,
            "z": 9,

            "elements": [
                "minecraft:furnace@5"
            ]
        },
        {
            "x": 1,
            "y": 0,
            "z": 9,

            "elements": [
                "minecraft:furnace@4"
            ]
        },
        {
            "x": 2,
            "y": 0,
            "z": 9,
            "elements": [
                "minecraft:concrete_powder@8"
            ]
        },
        {
            "x": -13,
            "y": 9,
            "z": 13,
            "elements": [
                "extrautils2:decorativesolid@1"
            ]
        },
        {
            "x": -12,
            "y": 9,
            "z": 13,
            "elements": [
                "chisel:antiblock@0"
            ]
        },
        {
            "x": -13,
            "y": 1,
            "z": 9,
            "elements": [
                "chisel:stonebrick2@9"
            ]
        },
        {
            "x": -12,
            "y": 1,
            "z": 9,
            "elements": [
                "chisel:antiblock@1"
            ]
        },
        {
            "x": -11,
            "y": 1,
            "z": 9,
            "elements": [
                "chisel:antiblock@0"
            ]
        },
        {
            "x": -10,
            "y": 1,
            "z": 9,
            "elements": [
                "chisel:antiblock@0"
            ]
        },
        {
            "x": -9,
            "y": 1,
            "z": 9,
            "elements": [
                "chisel:antiblock@0"
            ]
        },
        {
            "x": -8,
            "y": 1,
            "z": 9,
            "elements": [
                "chisel:antiblock@0"
            ]
        },
        {
            "x": -7,
            "y": 1,
            "z": 9,
            "elements": [
                "chisel:antiblock@0"
            ]
        },
        {
            "x": -6,
            "y": 1,
            "z": 9,
            "elements": [
                "chisel:antiblock@0"
            ]
        },
        {
            "x": -5,
            "y": 1,
            "z": 9,
            "elements": [
                "chisel:antiblock@0"
            ]
        },
        {
            "x": -4,
            "y": 1,
            "z": 9,
            "elements": [
                "chisel:antiblock@0"
            ]
        },
        {
            "x": 1,
            "y": 9,
            "z": 13,
            "elements": [
                "chisel:antiblock@0"
            ]
        },
        {
            "x": -3,
            "y": 1,
            "z": 9,
            "elements": [
                "chisel:antiblock@0"
            ]
        },
        {
            "x": -2,
            "y": 1,
            "z": 9,
            "elements": [
                "chisel:antiblock@0"
            ]
        },
        {
            "x": 2,
            "y": 9,
            "z": 13,
            "elements": [
                "extrautils2:decorativesolid@1"
            ]
        },
        {
            "x": -1,
            "y": 1,
            "z": 9,
            "elements": [
                "chisel:antiblock@0"
            ]
        },
        {
            "x": 0,
            "y": 1,
            "z": 9,
            "elements": [
                "chisel:antiblock@0"
            ]
        },
        {
            "x": 1,
            "y": 1,
            "z": 9,
            "elements": [
                "chisel:antiblock@1"
            ]
        },
        {
            "x": 2,
            "y": 1,
            "z": 9,
            "elements": [
                "chisel:stonebrick2@9"
            ]
        },
        {
            "x": -13,
            "y": 10,
            "z": 13,
            "elements": [
                "extrautils2:decorativesolid@1"
            ]
        },
        {
            "x": -12,
            "y": 10,
            "z": 13,
            "elements": [
                "chisel:antiblock@0"
            ]
        },
        {
            "x": -13,
            "y": 2,
            "z": 9,
            "elements": [
                "chisel:stonebrick2@9"
            ]
        },
        {
            "x": -12,
            "y": 2,
            "z": 9,
            "elements": [
                "chisel:antiblock@0"
            ]
        },
        {
            "x": 1,
            "y": 10,
            "z": 13,
            "elements": [
                "chisel:antiblock@0"
            ]
        },
        {
            "x": 2,
            "y": 10,
            "z": 13,
            "elements": [
                "extrautils2:decorativesolid@1"
            ]
        },
        {
            "x": 1,
            "y": 2,
            "z": 9,
            "elements": [
                "chisel:antiblock@0"
            ]
        },
        {
            "x": 2,
            "y": 2,
            "z": 9,
            "elements": [
                "chisel:stonebrick2@9"
            ]
        },
        {
            "x": -13,
            "y": 11,
            "z": 13,
            "elements": [
                "extrautils2:decorativesolid@1"
            ]
        },
        {
            "x": -12,
            "y": 11,
            "z": 13,
            "elements": [
                "chisel:antiblock@0"
            ]
        },
        {
            "x": -13,
            "y": 3,
            "z": 9,
            "elements": [
                "chisel:stonebrick2@9"
            ]
        },
        {
            "x": -12,
            "y": 3,
            "z": 9,
            "elements": [
                "chisel:antiblock@0"
            ]
        },
        {
            "x": 1,
            "y": 11,
            "z": 13,
            "elements": [
                "chisel:antiblock@0"
            ]
        },
        {
            "x": 2,
            "y": 11,
            "z": 13,
            "elements": [
                "extrautils2:decorativesolid@1"
            ]
        },
        {
            "x": 1,
            "y": 3,
            "z": 9,
            "elements": [
                "chisel:antiblock@0"
            ]
        },
        {
            "x": 2,
            "y": 3,
            "z": 9,
            "elements": [
                "chisel:stonebrick2@9"
            ]
        },
        {
            "x": -13,
            "y": 12,
            "z": 13,
            "elements": [
                "extrautils2:decorativesolid@1"
            ]
        },
        {
            "x": -12,
            "y": 12,
            "z": 13,
            "elements": [
                "chisel:antiblock@1"
            ]
        },
        {
            "x": -11,
            "y": 12,
            "z": 13,
            "elements": [
                "chisel:antiblock@0"
            ]
        },
        {
            "x": -10,
            "y": 12,
            "z": 13,
            "elements": [
                "chisel:antiblock@0"
            ]
        },
        {
            "x": -13,
            "y": 4,
            "z": 9,
            "elements": [
                "chisel:stonebrick2@9"
            ]
        },
        {
            "x": -9,
            "y": 12,
            "z": 13,
            "elements": [
                "chisel:antiblock@0"
            ]
        },
        {
            "x": -12,
            "y": 4,
            "z": 9,
            "elements": [
                "chisel:antiblock@0"
            ]
        },
        {
            "x": -8,
            "y": 12,
            "z": 13,
            "elements": [
                "chisel:antiblock@0"
            ]
        },
        {
            "x": -7,
            "y": 12,
            "z": 13,
            "elements": [
                "chisel:antiblock@0"
            ]
        },
        {
            "x": -6,
            "y": 12,
            "z": 13,
            "elements": [
                "chisel:antiblock@0"
            ]
        },
        {
            "x": -5,
            "y": 12,
            "z": 13,
            "elements": [
                "chisel:antiblock@0"
            ]
        },
        {
            "x": -4,
            "y": 12,
            "z": 13,
            "elements": [
                "chisel:antiblock@0"
            ]
        },
        {
            "x": -3,
            "y": 12,
            "z": 13,
            "elements": [
                "chisel:antiblock@0"
            ]
        },
        {
            "x": -2,
            "y": 12,
            "z": 13,
            "elements": [
                "chisel:antiblock@0"
            ]
        },
        {
            "x": -1,
            "y": 12,
            "z": 13,
            "elements": [
                "chisel:antiblock@0"
            ]
        },
        {
            "x": 0,
            "y": 12,
            "z": 13,
            "elements": [
                "chisel:antiblock@0"
            ]
        },
        {
            "x": 1,
            "y": 12,
            "z": 13,
            "elements": [
                "chisel:antiblock@1"
            ]
        },
        {
            "x": 2,
            "y": 12,
            "z": 13,
            "elements": [
                "extrautils2:decorativesolid@1"
            ]
        },
        {
            "x": 1,
            "y": 4,
            "z": 9,
            "elements": [
                "chisel:antiblock@0"
            ]
        },
        {
            "x": 2,
            "y": 4,
            "z": 9,
            "elements": [
                "chisel:stonebrick2@9"
            ]
        },
        {
            "x": -13,
            "y": 13,
            "z": 13,
            "elements": [
                "minecraft:concrete_powder@8"
            ]
        },
        {
            "x": -12,
            "y": 13,
            "z": 13,

            "elements": [
                "minecraft:furnace@5"
            ]
        },
        {
            "x": -11,
            "y": 13,
            "z": 13,

            "elements": [
                "minecraft:furnace@5"
            ]
        },
        {
            "x": -10,
            "y": 13,
            "z": 13,

            "elements": [
                "minecraft:furnace@5"
            ]
        },
        {
            "x": -13,
            "y": 5,
            "z": 9,
            "elements": [
                "chisel:stonebrick2@9"
            ]
        },
        {
            "x": -9,
            "y": 13,
            "z": 13,

            "elements": [
                "minecraft:furnace@5"
            ]
        },
        {
            "x": -12,
            "y": 5,
            "z": 9,
            "elements": [
                "chisel:antiblock@0"
            ]
        },
        {
            "x": -8,
            "y": 13,
            "z": 13,

            "elements": [
                "minecraft:furnace@5"
            ]
        },
        {
            "x": -7,
            "y": 13,
            "z": 13,

            "elements": [
                "minecraft:furnace@5"
            ]
        },
        {
            "x": -6,
            "y": 13,
            "z": 13,

            "elements": [
                "minecraft:furnace@5"
            ]
        },
        {
            "x": -5,
            "y": 13,
            "z": 13,

            "elements": [
                "minecraft:furnace@5"
            ]
        },
        {
            "x": -4,
            "y": 13,
            "z": 13,

            "elements": [
                "minecraft:furnace@5"
            ]
        },
        {
            "x": -3,
            "y": 13,
            "z": 13,

            "elements": [
                "minecraft:furnace@5"
            ]
        },
        {
            "x": -2,
            "y": 13,
            "z": 13,

            "elements": [
                "minecraft:furnace@5"
            ]
        },
        {
            "x": -1,
            "y": 13,
            "z": 13,

            "elements": [
                "minecraft:furnace@5"
            ]
        },
        {
            "x": 0,
            "y": 13,
            "z": 13,

            "elements": [
                "minecraft:furnace@5"
