{
	"registryname":"refining_furnace",
	"localizedname":"精炼熔炉",
	"color":"696969",
    "parts": [
        {
            "x": 0,
            "y": 0,
            "z": 0,
            "elements": [
                "modularmachinery:blockcontroller@2"
            ]
        },
        {
            "x": -1,
            "y": 0,
            "z": 0,
            "elements": [
                "modularmachinery:blockinputbus@6",
				"modularmachinery:blockinputbus@5",
				"modularmachinery:blockinputbus@4",
				"modularmachinery:blockinputbus@3",
				"modularmachinery:blockinputbus@2",
				"modularmachinery:blockinputbus@1",
				"modularmachinery:blockinputbus@0",
				"modularmachinery:blockoutputbus@6",
				"modularmachinery:blockoutputbus@5",
				"modularmachinery:blockoutputbus@4",
				"modularmachinery:blockoutputbus@3",
				"modularmachinery:blockoutputbus@2",
				"modularmachinery:blockoutputbus@1",
				"modularmachinery:blockoutputbus@0"
            ]
        },
        {
            "x": 1,
            "y": 2,
            "z": 1,
            "elements": [
                "embers:beam_cannon@0"
            ]
        },
        {
            "x": -2,
            "y": 0,
            "z": 0,
            "elements": [
                "extrautils2:decorativesolid@3"
            ]
        },
        {
            "x": 2,
            "y": 2,
            "z": 1,
            "elements": [
                "extrautils2:decorativesolid@0"
            ]
        },
        {
            "x": 1,
            "y": 0,
            "z": 0,
            "elements": [
                "modularmachinery:blockinputbus@6",
				"modularmachinery:blockinputbus@5",
				"modularmachinery:blockinputbus@4",
				"modularmachinery:blockinputbus@3",
				"modularmachinery:blockinputbus@2",
				"modularmachinery:blockinputbus@1",
				"modularmachinery:blockinputbus@0",
				"modularmachinery:blockoutputbus@6",
				"modularmachinery:blockoutputbus@5",
				"modularmachinery:blockoutputbus@4",
				"modularmachinery:blockoutputbus@3",
				"modularmachinery:blockoutputbus@2",
				"modularmachinery:blockoutputbus@1",
				"modularmachinery:blockoutputbus@0"
            ]
        },
        {
            "x": 2,
            "y": 0,
            "z": 0,
            "elements": [
                "extrautils2:decorativesolid@3"
            ]
        },
        {
            "x": -2,
            "y": 0,
            "z": 4,
            "elements": [
                "extrautils2:decorativesolid@3"
            ]
        },
        {
            "x": -1,
            "y": 0,
            "z": 4,
            "elements": [
				"extrautils2:decorativesolid@0",
				"modularmachinery:blockfluidinputhatch@7",
				"modularmachinery:blockfluidinputhatch@6",
				"modularmachinery:blockfluidinputhatch@5",
				"modularmachinery:blockfluidinputhatch@4",
				"modularmachinery:blockfluidinputhatch@3",
				"modularmachinery:blockfluidinputhatch@2",
				"modularmachinery:blockfluidinputhatch@1",
				"modularmachinery:blockfluidinputhatch@0"
            ]
        },
        {
            "x": 0,
            "y": 0,
            "z": 4,
            "elements": [
				"extrautils2:decorativesolid@0",
				"modularmachinery:blockfluidinputhatch@7",
				"modularmachinery:blockfluidinputhatch@6",
				"modularmachinery:blockfluidinputhatch@5",
				"modularmachinery:blockfluidinputhatch@4",
				"modularmachinery:blockfluidinputhatch@3",
				"modularmachinery:blockfluidinputhatch@2",
				"modularmachinery:blockfluidinputhatch@1",
				"modularmachinery:blockfluidinputhatch@0"
            ]
        },
        {
            "x": 1,
            "y": 0,
            "z": 4,
            "elements": [
				"extrautils2:decorativesolid@0",
				"modularmachinery:blockfluidinputhatch@7",
				"modularmachinery:blockfluidinputhatch@6",
				"modularmachinery:blockfluidinputhatch@5",
				"modularmachinery:blockfluidinputhatch@4",
				"modularmachinery:blockfluidinputhatch@3",
				"modularmachinery:blockfluidinputhatch@2",
				"modularmachinery:blockfluidinputhatch@1",
				"modularmachinery:blockfluidinputhatch@0"
            ]
        },
        {
            "x": 2,
            "y": 0,
            "z": 4,
            "elements": [
                "extrautils2:decorativesolid@3"
            ]
        },
        {
            "x": -2,
            "y": 3,
            "z": 1,
            "elements": [
                "extrautils2:decorativesolid@3"
            ]
        },
        {
            "x": 2,
            "y": -1,
            "z": 0,
            "elements": [
                "extrautils2:decorativesolid@3"
            ]
        },
        {
            "x": -2,
            "y": 1,
            "z": 0,
            "elements": [
                "extrautils2:decorativesolid@3"
            ]
        },
        {
            "x": -1,
            "y": 3,
            "z": 1,
            "elements": [
                "extrautils2:decorativesolid@1"
            ]
        },
        {
            "x": 1,
            "y": -1,
            "z": 0,
            "elements": [
                "extrautils2:decorativesolid@3"
            ]
        },
        {
            "x": 0,
            "y": -1,
            "z": 0,
            "elements": [
                "extrautils2:decorativesolid@3"
            ]
        },
        {
            "x": 0,
            "y": 3,
            "z": 1,
            "elements": [
                "extrautils2:decorativesolid@1"
            ]
        },
        {
            "x": -1,
            "y": 1,
            "z": 0,
            "elements": [
                "extrautils2:decorativesolid@3"
            ]
        },
        {
            "x": 1,
            "y": 3,
            "z": 1,
            "elements": [
                "extrautils2:decorativesolid@1"
            ]
        },
        {
            "x": 0,
            "y": 1,
            "z": 0,
            "elements": [
                "extrautils2:decorativesolid@3"
            ]
        },
        {
            "x": -1,
            "y": -1,
            "z": 0,
            "elements": [
                "extrautils2:decorativesolid@3"
            ]
        },
        {
            "x": -2,
            "y": -1,
            "z": 0,
            "elements": [
                "extrautils2:decorativesolid@3"
            ]
        },
        {
            "x": 2,
            "y": 3,
            "z": 1,
            "elements": [
                "extrautils2:decorativesolid@3"
            ]
        },
        {
            "x": 1,
            "y": 1,
            "z": 0,
            "elements": [
                "extrautils2:decorativesolid@3"
            ]
        },
        {
            "x": -2,
            "y": 1,
            "z": 4,
            "elements": [
                "extrautils2:decorativesolid@3"
            ]
        },
        {
            "x": 2,
            "y": 1,
            "z": 0,
            "elements": [
                "extrautils2:decorativesolid@3"
            ]
        },
        {
            "x": -2,
            "y": -1,
            "z": 3,
            "elements": [
                "extrautils2:decorativesolid@3"
            ]
        },
        {
            "x": -1,
            "y": 1,
            "z": 4,
            "elements": [
                "extrautils2:decorativesolid@3"
            ]
        },
        {
            "x": 0,
            "y": 1,
            "z": 4,
            "elements": [
                "extrautils2:decorativesolid@3"
            ]
        },
        {
            "x": -1,
            "y": -1,
            "z": 3,
            "elements": [
                "extrautils2:decorativesolid@0"
            ]
        },
        {
            "x": 0,
            "y": -1,
            "z": 3,
            "elements": [
                "extrautils2:decorativesolid@0"
            ]
        },
        {
            "x": 1,
            "y": 1,
            "z": 4,
            "elements": [
                "extrautils2:decorativesolid@3"
            ]
        },
        {
            "x": 2,
            "y": 1,
            "z": 4,
            "elements": [
                "extrautils2:decorativesolid@3"
            ]
        },
        {
            "x": 1,
            "y": -1,
            "z": 3,
            "elements": [
                "extrautils2:decorativesolid@0"
            ]
        },
        {
            "x": 2,
            "y": -1,
            "z": 3,
            "elements": [
                "extrautils2:decorativesolid@3"
            ]
        },
        {
            "x": -2,
            "y": 2,
            "z": 0,
            "elements": [
                "extrautils2:decorativesolid@3"
            ]
        },
        {
            "x": -1,
            "y": 2,
            "z": 0,
            "elements": [
                "extrautils2:decorativesolid@1"
            ]
        },
        {
            "x": 0,
            "y": 2,
            "z": 0,
            "elements": [
                "extrautils2:decorativesolid@1"
            ]
        },
        {
            "x": 1,
            "y": 2,
            "z": 0,
            "elements": [
                "extrautils2:decorativesolid@1"
            ]
        },
        {
            "x": -2,
            "y": 2,
            "z": 4,
            "elements": [
                "extrautils2:decorativesolid@3"
            ]
        },
        {
            "x": 2,
            "y": 2,
            "z": 0,
            "elements": [
                "extrautils2:decorativesolid@3"
            ]
        },
        {
            "x": -2,
            "y": 0,
            "z": 3,
            "elements": [
                "extrautils2:decorativesolid@0"
            ]
        },
        {
            "x": -1,
            "y": 2,
            "z": 4,
            "elements": [
				"extrautils2:decorativesolid@1",
				"modularmachinery:blockfluidinputhatch@7",
				"modularmachinery:blockfluidinputhatch@6",
				"modularmachinery:blockfluidinputhatch@5",
				"modularmachinery:blockfluidinputhatch@4",
				"modularmachinery:blockfluidinputhatch@3",
				"modularmachinery:blockfluidinputhatch@2",
				"modularmachinery:blockfluidinputhatch@1",
				"modularmachinery:blockfluidinputhatch@0"
            ]
        },
        {
            "x": 0,
            "y": 2,
            "z": 4,
            "elements": [
				"extrautils2:decorativesolid@1",
				"modularmachinery:blockfluidinputhatch@7",
				"modularmachinery:blockfluidinputhatch@6",
				"modularmachinery:blockfluidinputhatch@5",
				"modularmachinery:blockfluidinputhatch@4",
				"modularmachinery:blockfluidinputhatch@3",
				"modularmachinery:blockfluidinputhatch@2",
				"modularmachinery:blockfluidinputhatch@1",
				"modularmachinery:blockfluidinputhatch@0"
            ]
        },
        {
            "x": -1,
            "y": 0,
            "z": 3,
            "elements": [
                "embers:beam_cannon@1"
            ]
        },
        {
            "x": 0,
            "y": 0,
            "z": 3,
            "elements": [
                "embers:beam_cannon@1"
            ]
        },
        {
            "x": 1,
            "y": 2,
            "z": 4,
            "elements": [
				"extrautils2:decorativesolid@1",
				"modularmachinery:blockfluidinputhatch@7",
				"modularmachinery:blockfluidinputhatch@6",
				"modularmachinery:blockfluidinputhatch@5",
				"modularmachinery:blockfluidinputhatch@4",
				"modularmachinery:blockfluidinputhatch@3",
				"modularmachinery:blockfluidinputhatch@2",
				"modularmachinery:blockfluidinputhatch@1",
				"modularmachinery:blockfluidinputhatch@0"
            ]
        },
        {
            "x": 2,
            "y": 2,
            "z": 4,
            "elements": [
                "extrautils2:decorativesolid@3"
            ]
        },
        {
            "x": 1,
            "y": 0,
            "z": 3,
            "elements": [
                "embers:beam_cannon@1"
            ]
        },
        {
            "x": 2,
            "y": 0,
            "z": 3,
            "elements": [
                "extrautils2:decorativesolid@0"
            ]
        },
        {
            "x": -2,
            "y": 3,
            "z": 0,
            "elements": [
                "extrautils2:decorativesolid@3"
            ]
        },
        {
            "x": -1,
            "y": 3,
            "z": 0,
            "elements": [
                "extrautils2:decorativesolid@3"
            ]
        },
        {
            "x": 0,
            "y": 3,
            "z": 0,
            "elements": [
                "extrautils2:decorativesolid@3"
            ]
        },
        {
            "x": 1,
            "y": 3,
            "z": 0,
            "elements": [
                "extrautils2:decorativesolid@3"
            ]
        },
        {
            "x": -2,
            "y": 3,
            "z": 4,
            "elements": [
                "extrautils2:decorativesolid@3"
            ]
        },
        {
            "x": 2,
            "y": 3,
            "z": 0,
            "elements": [
                "extrautils2:decorativesolid@3"
            ]
        },
        {
            "x": -2,
            "y": 1,
            "z": 3,
            "elements": [
                "extrautils2:decorativesolid@3"
            ]
        },
        {
            "x": -1,
            "y": 3,
            "z": 4,
            "elements": [
                "extrautils2:decorativesolid@3"
            ]
        },
        {
            "x": 0,
            "y": 3,
            "z": 4,
            "elements": [
                "extrautils2:decorativesolid@3"
            ]
        },
        {
            "x": -2,
            "y": -1,
            "z": 2,
            "elements": [
                "extrautils2:decorativesolid@3"
            ]
        },
        {
            "x": -1,
            "y": 1,
            "z": 3,
            "elements": [
                "embers:archaic_light@0"
            ]
        },
        {
            "x": 1,
            "y": 3,
            "z": 4,
            "elements": [
                "extrautils2:decorativesolid@3"
            ]
        },
        {
            "x": 0,
            "y": 1,
            "z": 3,
            "elements": [
                "embers:archaic_light@0"
            ]
        },
        {
            "x": -1,
            "y": -1,
            "z": 2,
            "elements": [
                "extrautils2:decorativesolid@0"
            ]
        },
        {
            "x": 0,
            "y": -1,
            "z": 2,
            "elements": [
                "extrautils2:decorativesolid@0"
            ]
        },
        {
            "x": 2,
            "y": 3,
            "z": 4,
            "elements": [
                "extrautils2:decorativesolid@3"
            ]
        },
        {
            "x": 1,
            "y": 1,
            "z": 3,
            "elements": [
                "embers:archaic_light@0"
            ]
        },
        {
            "x": 2,
            "y": 1,
            "z": 3,
            "elements": [
                "extrautils2:decorativesolid@3"
            ]
        },
        {
            "x": 1,
            "y": -1,
            "z": 2,
            "elements": [
                "extrautils2:decorativesolid@0"
            ]
        },
        {
            "x": 2,
            "y": -1,
            "z": 2,
            "elements": [
                "extrautils2:decorativesolid@3"
            ]
        },
        {
            "x": -2,
            "y": 2,
            "z": 3,
            "elements": [
                "extrautils2:decorativesolid@0"
            ]
        },
        {
            "x": -2,
            "y": 0,
            "z": 2,
            "elements": [
                "extrautils2:decorativesolid@0"
            ]
        },
        {
            "x": -1,
            "y": 2,
            "z": 3,
            "elements": [
                "embers:beam_cannon@0"
            ]
        },
        {
            "x": 0,
            "y": 2,
            "z": 3,
            "elements": [
                "embers:beam_cannon@0"
            ]
        },
        {
            "x": -1,
            "y": 0,
            "z": 2,
            "elements": [
                "embers:beam_cannon@1"
            ]
        },
        {
            "x": 0,
            "y": 0,
            "z": 2,
            "elements": [
                "embers:beam_cannon@1"
            ]
        },
        {
            "x": 1,
            "y": 2,
            "z": 3,
            "elements": [
                "embers:beam_cannon@0"
            ]
        },
        {
            "x": 2,
            "y": 2,
            "z": 3,
            "elements": [
                "extrautils2:decorativesolid@0"
            ]
        },
        {
            "x": 1,
            "y": 0,
            "z": 2,
            "elements": [
                "embers:beam_cannon@1"
            ]
        },
        {
            "x": 2,
            "y": 0,
            "z": 2,
            "elements": [
                "extrautils2:decorativesolid@0"
            ]
        },
        {
            "x": -2,
            "y": 3,
            "z": 3,
            "elements": [
                "extrautils2:decorativesolid@3"
            ]
        },
        {
            "x": -2,
            "y": 1,
            "z": 2,
            "elements": [
                "extrautils2:decorativesolid@3"
            ]
        },
        {
            "x": -1,
            "y": 3,
            "z": 3,
            "elements": [
                "extrautils2:decorativesolid@1"
            ]
        },
        {
            "x": 0,
            "y": 3,
            "z": 3,
            "elements": [
                "extrautils2:decorativesolid@1"
            ]
        },
        {
            "x": -2,
            "y": -1,
            "z": 1,
            "elements": [
                "extrautils2:decorativesolid@3"
            ]
        },
        {
            "x": -1,
            "y": 1,
            "z": 2,
            "elements": [
                "embers:archaic_light@0"
            ]
        },
        {
            "x": 1,
            "y": 3,
            "z": 3,
            "elements": [
                "extrautils2:decorativesolid@1"
            ]
        },
        {
            "x": 0,
            "y": 1,
            "z": 2,
            "elements": [
                "thermalfoundation:fluid_cryotheum@0"
            ]
        },
        {
            "x": -1,
            "y": -1,
            "z": 1,
            "elements": [
                "extrautils2:decorativesolid@0"
            ]
        },
        {
            "x": 0,
            "y": -1,
            "z": 1,
            "elements": [
                "extrautils2:decorativesolid@0"
            ]
        },
        {
            "x": 2,
            "y": 3,
            "z": 3,
            "elements": [
                "extrautils2:decorativesolid@3"
            ]
        },
        {
            "x": 1,
            "y": 1,
            "z": 2,
            "elements": [
                "embers:archaic_light@0"
            ]
        },
        {
            "x": 2,
            "y": 1,
            "z": 2,
            "elements": [
                "extrautils2:decorativesolid@3"
            ]
        },
        {
            "x": 1,
            "y": -1,
            "z": 1,
            "elements": [
                "extrautils2:decorativesolid@0"
            ]
        },
        {
            "x": 2,
            "y": -1,
            "z": 1,
            "elements": [
                "extrautils2:decorativesolid@3"
            ]
        },
        {
            "x": -2,
            "y": 2,
            "z": 2,
            "elements": [
                "extrautils2:decorativesolid@0"
            ]
        },
        {
            "x": -2,
            "y": 0,
            "z": 1,
            "elements": [
                "extrautils2:decorativesolid@0"
            ]
        },
        {
            "x": -1,
            "y": 2,
            "z": 2,
            "elements": [
                "embers:beam_cannon@0"
            ]
        },
        {
            "x": 0,
            "y": 2,
            "z": 2,
            "elements": [
                "minecraft:redstone_block@0"
            ]
        },
        {
            "x": -1,
            "y": 0,
            "z": 1,
            "elements": [
                "embers:beam_cannon@1"
            ]
        },
        {
            "x": 0,
            "y": 0,
            "z": 1,
            "elements": [
                "embers:beam_cannon@1"
            ]
        },
        {
            "x": 1,
            "y": 2,
            "z": 2,
            "elements": [
                "embers:beam_cannon@0"
            ]
        },
        {
            "x": 2,
            "y": 2,
            "z": 2,
            "elements": [
                "extrautils2:decorativesolid@0"
            ]
        },
        {
            "x": 1,
            "y": 0,
            "z": 1,
            "elements": [
                "embers:beam_cannon@1"
            ]
        },
        {
            "x": 2,
            "y": 0,
            "z": 1,
            "elements": [
                "extrautils2:decorativesolid@0"
            ]
        },
        {
            "x": -2,
            "y": 3,
            "z": 2,
            "elements": [
                "extrautils2:decorativesolid@3"
            ]
        },
        {
            "x": -2,
            "y": 1,
            "z": 1,
            "elements": [
                "extrautils2:decorativesolid@3"
            ]
        },
        {
            "x": -1,
            "y": 3,
            "z": 2,
            "elements": [
                "extrautils2:decorativesolid@1"
            ]
        },
        {
            "x": 0,
            "y": 3,
            "z": 2,
            "elements": [
                "extrautils2:decorativesolid@1"
            ]
        },
        {
            "x": -1,
            "y": 1,
            "z": 1,
            "elements": [
                "embers:archaic_light@0"
            ]
        },
        {
            "x": 1,
            "y": 3,
            "z": 2,
            "elements": [
                "extrautils2:decorativesolid@1"
            ]
        },
        {
            "x": 0,
            "y": 1,
            "z": 1,
            "elements": [
                "embers:archaic_light@0"
            ]
        },
        {
            "x": 2,
            "y": 3,
            "z": 2,
            "elements": [
                "extrautils2:decorativesolid@3"
            ]
        },
        {
            "x": 1,
            "y": 1,
            "z": 1,
            "elements": [
                "embers:archaic_light@0"
            ]
        },
        {
            "x": 2,
            "y": 1,
            "z": 1,
            "elements": [
                "extrautils2:decorativesolid@3"
            ]
        },
        {
            "x": -2,
            "y": -1,
            "z": 4,
            "elements": [
                "extrautils2:decorativesolid@3"
            ]
        },
        {
            "x": -1,
            "y": -1,
            "z": 4,
            "elements": [
                "extrautils2:decorativesolid@3"
            ]
        },
        {
            "x": 0,
            "y": -1,
            "z": 4,
            "elements": [
                "extrautils2:decorativesolid@3"
            ]
        },
        {
            "x": 1,
            "y": -1,
            "z": 4,
            "elements": [
                "extrautils2:decorativesolid@3"
            ]
        },
        {
            "x": 2,
            "y": -1,
            "z": 4,
            "elements": [
                "extrautils2:decorativesolid@3"
            ]
        },
        {
            "x": -2,
            "y": 2,
            "z": 1,
            "elements": [
                "extrautils2:decorativesolid@0"
            ]
        },
        {
            "x": -1,
            "y": 2,
            "z": 1,
            "elements": [
                "embers:beam_cannon@0"
            ]
        },
        {
            "x": 0,
            "y": 2,
            "z": 1,
            "elements": [
                "embers:beam_cannon@0"
            ]
        }
    ]}